<?xml version='1.0' encoding='utf-8'?>
<robot name="bb_arm">
  <link name="base_link">
    <visual>
      <origin xyz="0 0 0.15" rpy="0 0 0" />
      <geometry>
        <box size="0.5 0.5 0.3" />
      </geometry>
      <material name="blue">
        <color rgba="0.3 0.0 1 1.0" />
      </material>
    </visual>
    <collision>
      <origin xyz="0 0 0.15" rpy="0 0 0" />
      <geometry>
        <box size="0.5 0.5 0.3" />
      </geometry>
    </collision>
    <inertial>
      <mass value="1.35" />
      <inertia ixx="1" ixy="0" ixz="0" iyy="1" iyz="0" izz="1" />
    </inertial>
  </link>
  <link name="act0Seg0">
    <visual>
      <origin xyz="0 0 0.0375" rpy="0 0 0" />
      <geometry>
        <box size="0.4 0.4 0.075" />
      </geometry>
      <material name="blue">
        <color rgba="0.3 0.0 1 1.0" />
      </material>
    </visual>
    <collision>
      <origin xyz="0 0 0.0375" rpy="0 0 0" />
      <geometry>
        <box size="0.4 0.4 0.075" />
      </geometry>
    </collision>
    <inertial>
      <mass value="0.15" />
      <inertia ixx="1" ixy="0" ixz="0" iyy="1" iyz="0" izz="1" />
    </inertial>
  </link>
  <joint name="base_link_to_act0Seg0" type="fixed">
    <parent link="base_link" />
    <child link="act0Seg0" />
    <origin xyz="0 0 0.3" rpy="0 0 0" />
    <axis xyz="1 0 0" />
  </joint>
  <link name="act0Seg1">
    <visual>
      <origin xyz="0 0 0.075" rpy="0 0 0" />
      <geometry>
        <box size="0.4 0.4 0.15" />
      </geometry>
      <material name="blue">
        <color rgba="0.3 0.0 1 1.0" />
      </material>
    </visual>
    <collision>
      <origin xyz="0 0 0.075" rpy="0 0 0" />
      <geometry>
        <box size="0.4 0.4 0.15" />
      </geometry>
    </collision>
    <inertial>
      <mass value="0.15" />
      <inertia ixx="1" ixy="0" ixz="0" iyy="1" iyz="0" izz="1" />
    </inertial>
  </link>
  <joint name="act0Seg0_to_act0Seg1_ax0" type="revolute">
    <parent link="act0Seg0" />
    <child link="act0Seg1" />
    <origin xyz="0 0 0.075" rpy="0 0 0" />
    <axis xyz="1 0 0" />
    <limit lower="-3.141592" upper="3.141592" effort="100" velocity="3" />
  </joint>
  <link name="act0Seg1helper_shape">
    <visual>
      <origin xyz="0 0 0.0" rpy="0 -1.5707963267948966 0" />
      <geometry>
        <cylinder length="0.4" radius="0.2" />
      </geometry>
      <material name="blue">
        <color rgba="0.3 0.0 1 1.0" />
      </material>
    </visual>
    <collision>
      <origin xyz="0 0 0.0" rpy="0 -1.5707963267948966 0" />
      <geometry>
        <cylinder length="0.4" radius="0.2" />
      </geometry>
    </collision>
    <inertial>
      <mass value="0.00015" />
      <inertia ixx="0.001" ixy="0.0" ixz="0.0" iyy="0.001" iyz="0.0" izz="0.001" />
    </inertial>
  </link>
  <joint name="act0Seg0_to_act0Seg1_ax0helper_shape" type="fixed">
    <parent link="act0Seg0" />
    <child link="act0Seg1helper_shape" />
    <origin xyz="0 0 0.075" rpy="0 0 0" />
    <axis xyz="1 0 0" />
  </joint>
  <link name="act0Seg2">
    <visual>
      <origin xyz="0 0 0.075" rpy="0 0 0" />
      <geometry>
        <box size="0.4 0.4 0.15" />
      </geometry>
      <material name="blue">
        <color rgba="0.3 0.0 1 1.0" />
      </material>
    </visual>
    <collision>
      <origin xyz="0 0 0.075" rpy="0 0 0" />
      <geometry>
        <box size="0.4 0.4 0.15" />
      </geometry>
    </collision>
    <inertial>
      <mass value="0.15" />
      <inertia ixx="1" ixy="0" ixz="0" iyy="1" iyz="0" izz="1" />
    </inertial>
  </link>
  <joint name="act0Seg1_to_act0Seg2_ax1" type="revolute">
    <parent link="act0Seg1" />
    <child link="act0Seg2" />
    <origin xyz="0 0 0.15" rpy="0 0 0" />
    <axis xyz="0 1 0" />
    <limit lower="-3.141592" upper="3.141592" effort="100" velocity="3" />
  </joint>
  <link name="act0Seg2helper_shape">
    <visual>
      <origin xyz="0 0 0.0" rpy="-1.5707963267948966 0 0" />
      <geometry>
        <cylinder length="0.4" radius="0.2" />
      </geometry>
      <material name="blue">
        <color rgba="0.3 0.0 1 1.0" />
      </material>
    </visual>
    <collision>
      <origin xyz="0 0 0.0" rpy="-1.5707963267948966 0 0" />
      <geometry>
        <cylinder length="0.4" radius="0.2" />
      </geometry>
    </collision>
    <inertial>
      <mass value="0.00015" />
      <inertia ixx="0.001" ixy="0.0" ixz="0.0" iyy="0.001" iyz="0.0" izz="0.001" />
    </inertial>
  </link>
  <joint name="act0Seg1_to_act0Seg2_ax1helper_shape" type="fixed">
    <parent link="act0Seg1" />
    <child link="act0Seg2helper_shape" />
    <origin xyz="0 0 0.15" rpy="0 0 0" />
    <axis xyz="1 0 0" />
  </joint>
  <link name="act0Seg3">
    <visual>
      <origin xyz="0 0 0.075" rpy="0 0 0" />
      <geometry>
        <box size="0.4 0.4 0.15" />
      </geometry>
      <material name="blue">
        <color rgba="0.3 0.0 1 1.0" />
      </material>
    </visual>
    <collision>
      <origin xyz="0 0 0.075" rpy="0 0 0" />
      <geometry>
        <box size="0.4 0.4 0.15" />
      </geometry>
    </collision>
    <inertial>
      <mass value="0.15" />
      <inertia ixx="1" ixy="0" ixz="0" iyy="1" iyz="0" izz="1" />
    </inertial>
  </link>
  <joint name="act0Seg2_to_act0Seg3_ax0" type="revolute">
    <parent link="act0Seg2" />
    <child link="act0Seg3" />
    <origin xyz="0 0 0.15" rpy="0 0 0" />
    <axis xyz="1 0 0" />
    <limit lower="-3.141592" upper="3.141592" effort="100" velocity="3" />
  </joint>
  <link name="act0Seg3helper_shape">
    <visual>
      <origin xyz="0 0 0.0" rpy="0 -1.5707963267948966 0" />
      <geometry>
        <cylinder length="0.4" radius="0.2" />
      </geometry>
      <material name="blue">
        <color rgba="0.3 0.0 1 1.0" />
      </material>
    </visual>
    <collision>
      <origin xyz="0 0 0.0" rpy="0 -1.5707963267948966 0" />
      <geometry>
        <cylinder length="0.4" radius="0.2" />
      </geometry>
    </collision>
    <inertial>
      <mass value="0.00015" />
      <inertia ixx="0.001" ixy="0.0" ixz="0.0" iyy="0.001" iyz="0.0" izz="0.001" />
    </inertial>
  </link>
  <joint name="act0Seg2_to_act0Seg3_ax0helper_shape" type="fixed">
    <parent link="act0Seg2" />
    <child link="act0Seg3helper_shape" />
    <origin xyz="0 0 0.15" rpy="0 0 0" />
    <axis xyz="1 0 0" />
  </joint>
  <link name="act0Seg4">
    <visual>
      <origin xyz="0 0 0.075" rpy="0 0 0" />
      <geometry>
        <box size="0.4 0.4 0.15" />
      </geometry>
      <material name="blue">
        <color rgba="0.3 0.0 1 1.0" />
      </material>
    </visual>
    <collision>
      <origin xyz="0 0 0.075" rpy="0 0 0" />
      <geometry>
        <box size="0.4 0.4 0.15" />
      </geometry>
    </collision>
    <inertial>
      <mass value="0.15" />
      <inertia ixx="1" ixy="0" ixz="0" iyy="1" iyz="0" izz="1" />
    </inertial>
  </link>
  <joint name="act0Seg3_to_act0Seg4_ax1" type="revolute">
    <parent link="act0Seg3" />
    <child link="act0Seg4" />
    <origin xyz="0 0 0.15" rpy="0 0 0" />
    <axis xyz="0 1 0" />
    <limit lower="-3.141592" upper="3.141592" effort="100" velocity="3" />
  </joint>
  <link name="act0Seg4helper_shape">
    <visual>
      <origin xyz="0 0 0.0" rpy="-1.5707963267948966 0 0" />
      <geometry>
        <cylinder length="0.4" radius="0.2" />
      </geometry>
      <material name="blue">
        <color rgba="0.3 0.0 1 1.0" />
      </material>
    </visual>
    <collision>
      <origin xyz="0 0 0.0" rpy="-1.5707963267948966 0 0" />
      <geometry>
        <cylinder length="0.4" radius="0.2" />
      </geometry>
    </collision>
    <inertial>
      <mass value="0.00015" />
      <inertia ixx="0.001" ixy="0.0" ixz="0.0" iyy="0.001" iyz="0.0" izz="0.001" />
    </inertial>
  </link>
  <joint name="act0Seg3_to_act0Seg4_ax1helper_shape" type="fixed">
    <parent link="act0Seg3" />
    <child link="act0Seg4helper_shape" />
    <origin xyz="0 0 0.15" rpy="0 0 0" />
    <axis xyz="1 0 0" />
  </joint>
  <link name="act0Seg5">
    <visual>
      <origin xyz="0 0 0.075" rpy="0 0 0" />
      <geometry>
        <box size="0.4 0.4 0.15" />
      </geometry>
      <material name="blue">
        <color rgba="0.3 0.0 1 1.0" />
      </material>
    </visual>
    <collision>
      <origin xyz="0 0 0.075" rpy="0 0 0" />
      <geometry>
        <box size="0.4 0.4 0.15" />
      </geometry>
    </collision>
    <inertial>
      <mass value="0.15" />
      <inertia ixx="1" ixy="0" ixz="0" iyy="1" iyz="0" izz="1" />
    </inertial>
  </link>
  <joint name="act0Seg4_to_act0Seg5_ax0" type="revolute">
    <parent link="act0Seg4" />
    <child link="act0Seg5" />
    <origin xyz="0 0 0.15" rpy="0 0 0" />
    <axis xyz="1 0 0" />
    <limit lower="-3.141592" upper="3.141592" effort="100" velocity="3" />
  </joint>
  <link name="act0Seg5helper_shape">
    <visual>
      <origin xyz="0 0 0.0" rpy="0 -1.5707963267948966 0" />
      <geometry>
        <cylinder length="0.4" radius="0.2" />
      </geometry>
      <material name="blue">
        <color rgba="0.3 0.0 1 1.0" />
      </material>
    </visual>
    <collision>
      <origin xyz="0 0 0.0" rpy="0 -1.5707963267948966 0" />
      <geometry>
        <cylinder length="0.4" radius="0.2" />
      </geometry>
    </collision>
    <inertial>
      <mass value="0.00015" />
      <inertia ixx="0.001" ixy="0.0" ixz="0.0" iyy="0.001" iyz="0.0" izz="0.001" />
    </inertial>
  </link>
  <joint name="act0Seg4_to_act0Seg5_ax0helper_shape" type="fixed">
    <parent link="act0Seg4" />
    <child link="act0Seg5helper_shape" />
    <origin xyz="0 0 0.15" rpy="0 0 0" />
    <axis xyz="1 0 0" />
  </joint>
  <link name="act0Seg6">
    <visual>
      <origin xyz="0 0 0.075" rpy="0 0 0" />
      <geometry>
        <box size="0.4 0.4 0.15" />
      </geometry>
      <material name="blue">
        <color rgba="0.3 0.0 1 1.0" />
      </material>
    </visual>
    <collision>
      <origin xyz="0 0 0.075" rpy="0 0 0" />
      <geometry>
        <box size="0.4 0.4 0.15" />
      </geometry>
    </collision>
    <inertial>
      <mass value="0.15" />
      <inertia ixx="1" ixy="0" ixz="0" iyy="1" iyz="0" izz="1" />
    </inertial>
  </link>
  <joint name="act0Seg5_to_act0Seg6_ax1" type="revolute">
    <parent link="act0Seg5" />
    <child link="act0Seg6" />
    <origin xyz="0 0 0.15" rpy="0 0 0" />
    <axis xyz="0 1 0" />
    <limit lower="-3.141592" upper="3.141592" effort="100" velocity="3" />
  </joint>
  <link name="act0Seg6helper_shape">
    <visual>
      <origin xyz="0 0 0.0" rpy="-1.5707963267948966 0 0" />
      <geometry>
        <cylinder length="0.4" radius="0.2" />
      </geometry>
      <material name="blue">
        <color rgba="0.3 0.0 1 1.0" />
      </material>
    </visual>
    <collision>
      <origin xyz="0 0 0.0" rpy="-1.5707963267948966 0 0" />
      <geometry>
        <cylinder length="0.4" radius="0.2" />
      </geometry>
    </collision>
    <inertial>
      <mass value="0.00015" />
      <inertia ixx="0.001" ixy="0.0" ixz="0.0" iyy="0.001" iyz="0.0" izz="0.001" />
    </inertial>
  </link>
  <joint name="act0Seg5_to_act0Seg6_ax1helper_shape" type="fixed">
    <parent link="act0Seg5" />
    <child link="act0Seg6helper_shape" />
    <origin xyz="0 0 0.15" rpy="0 0 0" />
    <axis xyz="1 0 0" />
  </joint>
  <link name="act0Seg7">
    <visual>
      <origin xyz="0 0 0.075" rpy="0 0 0" />
      <geometry>
        <box size="0.4 0.4 0.15" />
      </geometry>
      <material name="blue">
        <color rgba="0.3 0.0 1 1.0" />
      </material>
    </visual>
    <collision>
      <origin xyz="0 0 0.075" rpy="0 0 0" />
      <geometry>
        <box size="0.4 0.4 0.15" />
      </geometry>
    </collision>
    <inertial>
      <mass value="0.15" />
      <inertia ixx="1" ixy="0" ixz="0" iyy="1" iyz="0" izz="1" />
    </inertial>
  </link>
  <joint name="act0Seg6_to_act0Seg7_ax0" type="revolute">
    <parent link="act0Seg6" />
    <child link="act0Seg7" />
    <origin xyz="0 0 0.15" rpy="0 0 0" />
    <axis xyz="1 0 0" />
    <limit lower="-3.141592" upper="3.141592" effort="100" velocity="3" />
  </joint>
  <link name="act0Seg7helper_shape">
    <visual>
      <origin xyz="0 0 0.0" rpy="0 -1.5707963267948966 0" />
      <geometry>
        <cylinder length="0.4" radius="0.2" />
      </geometry>
      <material name="blue">
        <color rgba="0.3 0.0 1 1.0" />
      </material>
    </visual>
    <collision>
      <origin xyz="0 0 0.0" rpy="0 -1.5707963267948966 0" />
      <geometry>
        <cylinder length="0.4" radius="0.2" />
      </geometry>
    </collision>
    <inertial>
      <mass value="0.00015" />
      <inertia ixx="0.001" ixy="0.0" ixz="0.0" iyy="0.001" iyz="0.0" izz="0.001" />
    </inertial>
  </link>
  <joint name="act0Seg6_to_act0Seg7_ax0helper_shape" type="fixed">
    <parent link="act0Seg6" />
    <child link="act0Seg7helper_shape" />
    <origin xyz="0 0 0.15" rpy="0 0 0" />
    <axis xyz="1 0 0" />
  </joint>
  <link name="act0Seg8">
    <visual>
      <origin xyz="0 0 0.075" rpy="0 0 0" />
      <geometry>
        <box size="0.4 0.4 0.15" />
      </geometry>
      <material name="blue">
        <color rgba="0.3 0.0 1 1.0" />
      </material>
    </visual>
    <collision>
      <origin xyz="0 0 0.075" rpy="0 0 0" />
      <geometry>
        <box size="0.4 0.4 0.15" />
      </geometry>
    </collision>
    <inertial>
      <mass value="0.15" />
      <inertia ixx="1" ixy="0" ixz="0" iyy="1" iyz="0" izz="1" />
    </inertial>
  </link>
  <joint name="act0Seg7_to_act0Seg8_ax1" type="revolute">
    <parent link="act0Seg7" />
    <child link="act0Seg8" />
    <origin xyz="0 0 0.15" rpy="0 0 0" />
    <axis xyz="0 1 0" />
    <limit lower="-3.141592" upper="3.141592" effort="100" velocity="3" />
  </joint>
  <link name="act0Seg8helper_shape">
    <visual>
      <origin xyz="0 0 0.0" rpy="-1.5707963267948966 0 0" />
      <geometry>
        <cylinder length="0.4" radius="0.2" />
      </geometry>
      <material name="blue">
        <color rgba="0.3 0.0 1 1.0" />
      </material>
    </visual>
    <collision>
      <origin xyz="0 0 0.0" rpy="-1.5707963267948966 0 0" />
      <geometry>
        <cylinder length="0.4" radius="0.2" />
      </geometry>
    </collision>
    <inertial>
      <mass value="0.00015" />
      <inertia ixx="0.001" ixy="0.0" ixz="0.0" iyy="0.001" iyz="0.0" izz="0.001" />
    </inertial>
  </link>
  <joint name="act0Seg7_to_act0Seg8_ax1helper_shape" type="fixed">
    <parent link="act0Seg7" />
    <child link="act0Seg8helper_shape" />
    <origin xyz="0 0 0.15" rpy="0 0 0" />
    <axis xyz="1 0 0" />
  </joint>
  <link name="act0Seg9">
    <visual>
      <origin xyz="0 0 0.075" rpy="0 0 0" />
      <geometry>
        <box size="0.4 0.4 0.15" />
      </geometry>
      <material name="blue">
        <color rgba="0.3 0.0 1 1.0" />
      </material>
    </visual>
    <collision>
      <origin xyz="0 0 0.075" rpy="0 0 0" />
      <geometry>
        <box size="0.4 0.4 0.15" />
      </geometry>
    </collision>
    <inertial>
      <mass value="0.15" />
      <inertia ixx="1" ixy="0" ixz="0" iyy="1" iyz="0" izz="1" />
    </inertial>
  </link>
  <joint name="act0Seg8_to_act0Seg9_ax0" type="revolute">
    <parent link="act0Seg8" />
    <child link="act0Seg9" />
    <origin xyz="0 0 0.15" rpy="0 0 0" />
    <axis xyz="1 0 0" />
    <limit lower="-3.141592" upper="3.141592" effort="100" velocity="3" />
  </joint>
  <link name="act0Seg9helper_shape">
    <visual>
      <origin xyz="0 0 0.0" rpy="0 -1.5707963267948966 0" />
      <geometry>
        <cylinder length="0.4" radius="0.2" />
      </geometry>
      <material name="blue">
        <color rgba="0.3 0.0 1 1.0" />
      </material>
    </visual>
    <collision>
      <origin xyz="0 0 0.0" rpy="0 -1.5707963267948966 0" />
      <geometry>
        <cylinder length="0.4" radius="0.2" />
      </geometry>
    </collision>
    <inertial>
      <mass value="0.00015" />
      <inertia ixx="0.001" ixy="0.0" ixz="0.0" iyy="0.001" iyz="0.0" izz="0.001" />
    </inertial>
  </link>
  <joint name="act0Seg8_to_act0Seg9_ax0helper_shape" type="fixed">
    <parent link="act0Seg8" />
    <child link="act0Seg9helper_shape" />
    <origin xyz="0 0 0.15" rpy="0 0 0" />
    <axis xyz="1 0 0" />
  </joint>
  <link name="act0Seg10">
    <visual>
      <origin xyz="0 0 0.0375" rpy="0 0 0" />
      <geometry>
        <box size="0.4 0.4 0.075" />
      </geometry>
      <material name="blue">
        <color rgba="0.3 0.0 1 1.0" />
      </material>
    </visual>
    <collision>
      <origin xyz="0 0 0.0375" rpy="0 0 0" />
      <geometry>
        <box size="0.4 0.4 0.075" />
      </geometry>
    </collision>
    <inertial>
      <mass value="0.15" />
      <inertia ixx="1" ixy="0" ixz="0" iyy="1" iyz="0" izz="1" />
    </inertial>
  </link>
  <joint name="act0Seg9_to_act0Seg10_ax1" type="revolute">
    <parent link="act0Seg9" />
    <child link="act0Seg10" />
    <origin xyz="0 0 0.15" rpy="0 0 0" />
    <axis xyz="0 1 0" />
    <limit lower="-3.141592" upper="3.141592" effort="100" velocity="3" />
  </joint>
  <link name="act0Seg10helper_shape">
    <visual>
      <origin xyz="0 0 0.0" rpy="-1.5707963267948966 0 0" />
      <geometry>
        <cylinder length="0.4" radius="0.2" />
      </geometry>
      <material name="blue">
        <color rgba="0.3 0.0 1 1.0" />
      </material>
    </visual>
    <collision>
      <origin xyz="0 0 0.0" rpy="-1.5707963267948966 0 0" />
      <geometry>
        <cylinder length="0.4" radius="0.2" />
      </geometry>
    </collision>
    <inertial>
      <mass value="0.00015" />
      <inertia ixx="0.001" ixy="0.0" ixz="0.0" iyy="0.001" iyz="0.0" izz="0.001" />
    </inertial>
  </link>
  <joint name="act0Seg9_to_act0Seg10_ax1helper_shape" type="fixed">
    <parent link="act0Seg9" />
    <child link="act0Seg10helper_shape" />
    <origin xyz="0 0 0.15" rpy="0 0 0" />
    <axis xyz="1 0 0" />
  </joint>
  <link name="act1Seg0">
    <visual>
      <origin xyz="0 0 0.0375" rpy="0 0 0" />
      <geometry>
        <box size="0.4 0.4 0.075" />
      </geometry>
      <material name="blue">
        <color rgba="0.3 0.0 1 1.0" />
      </material>
    </visual>
    <collision>
      <origin xyz="0 0 0.0375" rpy="0 0 0" />
      <geometry>
        <box size="0.4 0.4 0.075" />
      </geometry>
    </collision>
    <inertial>
      <mass value="0.15" />
      <inertia ixx="1" ixy="0" ixz="0" iyy="1" iyz="0" izz="1" />
    </inertial>
  </link>
  <joint name="act0Seg10_to_act1Seg0_ax1" type="fixed">
    <parent link="act0Seg10" />
    <child link="act1Seg0" />
    <origin xyz="0 0 0.075" rpy="0 0 0" />
    <axis xyz="0 1 0" />
    <limit lower="-3.141592" upper="3.141592" effort="100" velocity="3" />
  </joint>
  <link name="act1Seg1">
    <visual>
      <origin xyz="0 0 0.075" rpy="0 0 0" />
      <geometry>
        <box size="0.4 0.4 0.15" />
      </geometry>
      <material name="blue">
        <color rgba="0.3 0.0 1 1.0" />
      </material>
    </visual>
    <collision>
      <origin xyz="0 0 0.075" rpy="0 0 0" />
      <geometry>
        <box size="0.4 0.4 0.15" />
      </geometry>
    </collision>
    <inertial>
      <mass value="0.15" />
      <inertia ixx="1" ixy="0" ixz="0" iyy="1" iyz="0" izz="1" />
    </inertial>
  </link>
  <joint name="act1Seg0_to_act1Seg1_ax0" type="revolute">
    <parent link="act1Seg0" />
    <child link="act1Seg1" />
    <origin xyz="0 0 0.075" rpy="0 0 0" />
    <axis xyz="1 0 0" />
    <limit lower="-3.141592" upper="3.141592" effort="100" velocity="3" />
  </joint>
  <link name="act1Seg1helper_shape">
    <visual>
      <origin xyz="0 0 0.0" rpy="0 -1.5707963267948966 0" />
      <geometry>
        <cylinder length="0.4" radius="0.2" />
      </geometry>
      <material name="blue">
        <color rgba="0.3 0.0 1 1.0" />
      </material>
    </visual>
    <collision>
      <origin xyz="0 0 0.0" rpy="0 -1.5707963267948966 0" />
      <geometry>
        <cylinder length="0.4" radius="0.2" />
      </geometry>
    </collision>
    <inertial>
      <mass value="0.00015" />
      <inertia ixx="0.001" ixy="0.0" ixz="0.0" iyy="0.001" iyz="0.0" izz="0.001" />
    </inertial>
  </link>
  <joint name="act1Seg0_to_act1Seg1_ax0helper_shape" type="fixed">
    <parent link="act1Seg0" />
    <child link="act1Seg1helper_shape" />
    <origin xyz="0 0 0.075" rpy="0 0 0" />
    <axis xyz="1 0 0" />
  </joint>
  <link name="act1Seg2">
    <visual>
      <origin xyz="0 0 0.075" rpy="0 0 0" />
      <geometry>
        <box size="0.4 0.4 0.15" />
      </geometry>
      <material name="blue">
        <color rgba="0.3 0.0 1 1.0" />
      </material>
    </visual>
    <collision>
      <origin xyz="0 0 0.075" rpy="0 0 0" />
      <geometry>
        <box size="0.4 0.4 0.15" />
      </geometry>
    </collision>
    <inertial>
      <mass value="0.15" />
      <inertia ixx="1" ixy="0" ixz="0" iyy="1" iyz="0" izz="1" />
    </inertial>
  </link>
  <joint name="act1Seg1_to_act1Seg2_ax1" type="revolute">
    <parent link="act1Seg1" />
    <child link="act1Seg2" />
    <origin xyz="0 0 0.15" rpy="0 0 0" />
    <axis xyz="0 1 0" />
    <limit lower="-3.141592" upper="3.141592" effort="100" velocity="3" />
  </joint>
  <link name="act1Seg2helper_shape">
    <visual>
      <origin xyz="0 0 0.0" rpy="-1.5707963267948966 0 0" />
      <geometry>
        <cylinder length="0.4" radius="0.2" />
      </geometry>
      <material name="blue">
        <color rgba="0.3 0.0 1 1.0" />
      </material>
    </visual>
    <collision>
      <origin xyz="0 0 0.0" rpy="-1.5707963267948966 0 0" />
      <geometry>
        <cylinder length="0.4" radius="0.2" />
      </geometry>
    </collision>
    <inertial>
      <mass value="0.00015" />
      <inertia ixx="0.001" ixy="0.0" ixz="0.0" iyy="0.001" iyz="0.0" izz="0.001" />
    </inertial>
  </link>
  <joint name="act1Seg1_to_act1Seg2_ax1helper_shape" type="fixed">
    <parent link="act1Seg1" />
    <child link="act1Seg2helper_shape" />
    <origin xyz="0 0 0.15" rpy="0 0 0" />
    <axis xyz="1 0 0" />
  </joint>
  <link name="act1Seg3">
    <visual>
      <origin xyz="0 0 0.075" rpy="0 0 0" />
      <geometry>
        <box size="0.4 0.4 0.15" />
      </geometry>
      <material name="blue">
        <color rgba="0.3 0.0 1 1.0" />
      </material>
    </visual>
    <collision>
      <origin xyz="0 0 0.075" rpy="0 0 0" />
      <geometry>
        <box size="0.4 0.4 0.15" />
      </geometry>
    </collision>
    <inertial>
      <mass value="0.15" />
      <inertia ixx="1" ixy="0" ixz="0" iyy="1" iyz="0" izz="1" />
    </inertial>
  </link>
  <joint name="act1Seg2_to_act1Seg3_ax0" type="revolute">
    <parent link="act1Seg2" />
    <child link="act1Seg3" />
    <origin xyz="0 0 0.15" rpy="0 0 0" />
    <axis xyz="1 0 0" />
    <limit lower="-3.141592" upper="3.141592" effort="100" velocity="3" />
  </joint>
  <link name="act1Seg3helper_shape">
    <visual>
      <origin xyz="0 0 0.0" rpy="0 -1.5707963267948966 0" />
      <geometry>
        <cylinder length="0.4" radius="0.2" />
      </geometry>
      <material name="blue">
        <color rgba="0.3 0.0 1 1.0" />
      </material>
    </visual>
    <collision>
      <origin xyz="0 0 0.0" rpy="0 -1.5707963267948966 0" />
      <geometry>
        <cylinder length="0.4" radius="0.2" />
      </geometry>
    </collision>
    <inertial>
      <mass value="0.00015" />
      <inertia ixx="0.001" ixy="0.0" ixz="0.0" iyy="0.001" iyz="0.0" izz="0.001" />
    </inertial>
  </link>
  <joint name="act1Seg2_to_act1Seg3_ax0helper_shape" type="fixed">
    <parent link="act1Seg2" />
    <child link="act1Seg3helper_shape" />
    <origin xyz="0 0 0.15" rpy="0 0 0" />
    <axis xyz="1 0 0" />
  </joint>
  <link name="act1Seg4">
    <visual>
      <origin xyz="0 0 0.075" rpy="0 0 0" />
      <geometry>
        <box size="0.4 0.4 0.15" />
      </geometry>
      <material name="blue">
        <color rgba="0.3 0.0 1 1.0" />
      </material>
    </visual>
    <collision>
      <origin xyz="0 0 0.075" rpy="0 0 0" />
      <geometry>
        <box size="0.4 0.4 0.15" />
      </geometry>
    </collision>
    <inertial>
      <mass value="0.15" />
      <inertia ixx="1" ixy="0" ixz="0" iyy="1" iyz="0" izz="1" />
    </inertial>
  </link>
  <joint name="act1Seg3_to_act1Seg4_ax1" type="revolute">
    <parent link="act1Seg3" />
    <child link="act1Seg4" />
    <origin xyz="0 0 0.15" rpy="0 0 0" />
    <axis xyz="0 1 0" />
    <limit lower="-3.141592" upper="3.141592" effort="100" velocity="3" />
  </joint>
  <link name="act1Seg4helper_shape">
    <visual>
      <origin xyz="0 0 0.0" rpy="-1.5707963267948966 0 0" />
      <geometry>
        <cylinder length="0.4" radius="0.2" />
      </geometry>
      <material name="blue">
        <color rgba="0.3 0.0 1 1.0" />
      </material>
    </visual>
    <collision>
      <origin xyz="0 0 0.0" rpy="-1.5707963267948966 0 0" />
      <geometry>
        <cylinder length="0.4" radius="0.2" />
      </geometry>
    </collision>
    <inertial>
      <mass value="0.00015" />
      <inertia ixx="0.001" ixy="0.0" ixz="0.0" iyy="0.001" iyz="0.0" izz="0.001" />
    </inertial>
  </link>
  <joint name="act1Seg3_to_act1Seg4_ax1helper_shape" type="fixed">
    <parent link="act1Seg3" />
    <child link="act1Seg4helper_shape" />
    <origin xyz="0 0 0.15" rpy="0 0 0" />
    <axis xyz="1 0 0" />
  </joint>
  <link name="act1Seg5">
    <visual>
      <origin xyz="0 0 0.075" rpy="0 0 0" />
      <geometry>
        <box size="0.4 0.4 0.15" />
      </geometry>
      <material name="blue">
        <color rgba="0.3 0.0 1 1.0" />
      </material>
    </visual>
    <collision>
      <origin xyz="0 0 0.075" rpy="0 0 0" />
      <geometry>
        <box size="0.4 0.4 0.15" />
      </geometry>
    </collision>
    <inertial>
      <mass value="0.15" />
      <inertia ixx="1" ixy="0" ixz="0" iyy="1" iyz="0" izz="1" />
    </inertial>
  </link>
  <joint name="act1Seg4_to_act1Seg5_ax0" type="revolute">
    <parent link="act1Seg4" />
    <child link="act1Seg5" />
    <origin xyz="0 0 0.15" rpy="0 0 0" />
    <axis xyz="1 0 0" />
    <limit lower="-3.141592" upper="3.141592" effort="100" velocity="3" />
  </joint>
  <link name="act1Seg5helper_shape">
    <visual>
      <origin xyz="0 0 0.0" rpy="0 -1.5707963267948966 0" />
      <geometry>
        <cylinder length="0.4" radius="0.2" />
      </geometry>
      <material name="blue">
        <color rgba="0.3 0.0 1 1.0" />
      </material>
    </visual>
    <collision>
      <origin xyz="0 0 0.0" rpy="0 -1.5707963267948966 0" />
      <geometry>
        <cylinder length="0.4" radius="0.2" />
      </geometry>
    </collision>
    <inertial>
      <mass value="0.00015" />
      <inertia ixx="0.001" ixy="0.0" ixz="0.0" iyy="0.001" iyz="0.0" izz="0.001" />
    </inertial>
  </link>
  <joint name="act1Seg4_to_act1Seg5_ax0helper_shape" type="fixed">
    <parent link="act1Seg4" />
    <child link="act1Seg5helper_shape" />
    <origin xyz="0 0 0.15" rpy="0 0 0" />
    <axis xyz="1 0 0" />
  </joint>
  <link name="act1Seg6">
    <visual>
      <origin xyz="0 0 0.075" rpy="0 0 0" />
      <geometry>
        <box size="0.4 0.4 0.15" />
      </geometry>
      <material name="blue">
        <color rgba="0.3 0.0 1 1.0" />
      </material>
    </visual>
    <collision>
      <origin xyz="0 0 0.075" rpy="0 0 0" />
      <geometry>
        <box size="0.4 0.4 0.15" />
      </geometry>
    </collision>
    <inertial>
      <mass value="0.15" />
      <inertia ixx="1" ixy="0" ixz="0" iyy="1" iyz="0" izz="1" />
    </inertial>
  </link>
  <joint name="act1Seg5_to_act1Seg6_ax1" type="revolute">
    <parent link="act1Seg5" />
    <child link="act1Seg6" />
    <origin xyz="0 0 0.15" rpy="0 0 0" />
    <axis xyz="0 1 0" />
    <limit lower="-3.141592" upper="3.141592" effort="100" velocity="3" />
  </joint>
  <link name="act1Seg6helper_shape">
    <visual>
      <origin xyz="0 0 0.0" rpy="-1.5707963267948966 0 0" />
      <geometry>
        <cylinder length="0.4" radius="0.2" />
      </geometry>
      <material name="blue">
        <color rgba="0.3 0.0 1 1.0" />
      </material>
    </visual>
    <collision>
      <origin xyz="0 0 0.0" rpy="-1.5707963267948966 0 0" />
      <geometry>
        <cylinder length="0.4" radius="0.2" />
      </geometry>
    </collision>
    <inertial>
      <mass value="0.00015" />
      <inertia ixx="0.001" ixy="0.0" ixz="0.0" iyy="0.001" iyz="0.0" izz="0.001" />
    </inertial>
  </link>
  <joint name="act1Seg5_to_act1Seg6_ax1helper_shape" type="fixed">
    <parent link="act1Seg5" />
    <child link="act1Seg6helper_shape" />
    <origin xyz="0 0 0.15" rpy="0 0 0" />
    <axis xyz="1 0 0" />
  </joint>
  <link name="act1Seg7">
    <visual>
      <origin xyz="0 0 0.075" rpy="0 0 0" />
      <geometry>
        <box size="0.4 0.4 0.15" />
      </geometry>
      <material name="blue">
        <color rgba="0.3 0.0 1 1.0" />
      </material>
    </visual>
    <collision>
      <origin xyz="0 0 0.075" rpy="0 0 0" />
      <geometry>
        <box size="0.4 0.4 0.15" />
      </geometry>
    </collision>
    <inertial>
      <mass value="0.15" />
      <inertia ixx="1" ixy="0" ixz="0" iyy="1" iyz="0" izz="1" />
    </inertial>
  </link>
  <joint name="act1Seg6_to_act1Seg7_ax0" type="revolute">
    <parent link="act1Seg6" />
    <child link="act1Seg7" />
    <origin xyz="0 0 0.15" rpy="0 0 0" />
    <axis xyz="1 0 0" />
    <limit lower="-3.141592" upper="3.141592" effort="100" velocity="3" />
  </joint>
  <link name="act1Seg7helper_shape">
    <visual>
      <origin xyz="0 0 0.0" rpy="0 -1.5707963267948966 0" />
      <geometry>
        <cylinder length="0.4" radius="0.2" />
      </geometry>
      <material name="blue">
        <color rgba="0.3 0.0 1 1.0" />
      </material>
    </visual>
    <collision>
      <origin xyz="0 0 0.0" rpy="0 -1.5707963267948966 0" />
      <geometry>
        <cylinder length="0.4" radius="0.2" />
      </geometry>
    </collision>
    <inertial>
      <mass value="0.00015" />
      <inertia ixx="0.001" ixy="0.0" ixz="0.0" iyy="0.001" iyz="0.0" izz="0.001" />
    </inertial>
  </link>
  <joint name="act1Seg6_to_act1Seg7_ax0helper_shape" type="fixed">
    <parent link="act1Seg6" />
    <child link="act1Seg7helper_shape" />
    <origin xyz="0 0 0.15" rpy="0 0 0" />
    <axis xyz="1 0 0" />
  </joint>
  <link name="act1Seg8">
    <visual>
      <origin xyz="0 0 0.075" rpy="0 0 0" />
      <geometry>
        <box size="0.4 0.4 0.15" />
      </geometry>
      <material name="blue">
        <color rgba="0.3 0.0 1 1.0" />
      </material>
    </visual>
    <collision>
      <origin xyz="0 0 0.075" rpy="0 0 0" />
      <geometry>
        <box size="0.4 0.4 0.15" />
      </geometry>
    </collision>
    <inertial>
      <mass value="0.15" />
      <inertia ixx="1" ixy="0" ixz="0" iyy="1" iyz="0" izz="1" />
    </inertial>
  </link>
  <joint name="act1Seg7_to_act1Seg8_ax1" type="revolute">
    <parent link="act1Seg7" />
    <child link="act1Seg8" />
    <origin xyz="0 0 0.15" rpy="0 0 0" />
    <axis xyz="0 1 0" />
    <limit lower="-3.141592" upper="3.141592" effort="100" velocity="3" />
  </joint>
  <link name="act1Seg8helper_shape">
    <visual>
      <origin xyz="0 0 0.0" rpy="-1.5707963267948966 0 0" />
      <geometry>
        <cylinder length="0.4" radius="0.2" />
      </geometry>
      <material name="blue">
        <color rgba="0.3 0.0 1 1.0" />
      </material>
    </visual>
    <collision>
      <origin xyz="0 0 0.0" rpy="-1.5707963267948966 0 0" />
      <geometry>
        <cylinder length="0.4" radius="0.2" />
      </geometry>
    </collision>
    <inertial>
      <mass value="0.00015" />
      <inertia ixx="0.001" ixy="0.0" ixz="0.0" iyy="0.001" iyz="0.0" izz="0.001" />
    </inertial>
  </link>
  <joint name="act1Seg7_to_act1Seg8_ax1helper_shape" type="fixed">
    <parent link="act1Seg7" />
    <child link="act1Seg8helper_shape" />
    <origin xyz="0 0 0.15" rpy="0 0 0" />
    <axis xyz="1 0 0" />
  </joint>
  <link name="act1Seg9">
    <visual>
      <origin xyz="0 0 0.075" rpy="0 0 0" />
      <geometry>
        <box size="0.4 0.4 0.15" />
      </geometry>
      <material name="blue">
        <color rgba="0.3 0.0 1 1.0" />
      </material>
    </visual>
    <collision>
      <origin xyz="0 0 0.075" rpy="0 0 0" />
      <geometry>
        <box size="0.4 0.4 0.15" />
      </geometry>
    </collision>
    <inertial>
      <mass value="0.15" />
      <inertia ixx="1" ixy="0" ixz="0" iyy="1" iyz="0" izz="1" />
    </inertial>
  </link>
  <joint name="act1Seg8_to_act1Seg9_ax0" type="revolute">
    <parent link="act1Seg8" />
    <child link="act1Seg9" />
    <origin xyz="0 0 0.15" rpy="0 0 0" />
    <axis xyz="1 0 0" />
    <limit lower="-3.141592" upper="3.141592" effort="100" velocity="3" />
  </joint>
  <link name="act1Seg9helper_shape">
    <visual>
      <origin xyz="0 0 0.0" rpy="0 -1.5707963267948966 0" />
      <geometry>
        <cylinder length="0.4" radius="0.2" />
      </geometry>
      <material name="blue">
        <color rgba="0.3 0.0 1 1.0" />
      </material>
    </visual>
    <collision>
      <origin xyz="0 0 0.0" rpy="0 -1.5707963267948966 0" />
      <geometry>
        <cylinder length="0.4" radius="0.2" />
      </geometry>
    </collision>
    <inertial>
      <mass value="0.00015" />
      <inertia ixx="0.001" ixy="0.0" ixz="0.0" iyy="0.001" iyz="0.0" izz="0.001" />
    </inertial>
  </link>
  <joint name="act1Seg8_to_act1Seg9_ax0helper_shape" type="fixed">
    <parent link="act1Seg8" />
    <child link="act1Seg9helper_shape" />
    <origin xyz="0 0 0.15" rpy="0 0 0" />
    <axis xyz="1 0 0" />
  </joint>
  <link name="act1Seg10">
    <visual>
      <origin xyz="0 0 0.0375" rpy="0 0 0" />
      <geometry>
        <box size="0.4 0.4 0.075" />
      </geometry>
      <material name="blue">
        <color rgba="0.3 0.0 1 1.0" />
      </material>
    </visual>
    <collision>
      <origin xyz="0 0 0.0375" rpy="0 0 0" />
      <geometry>
        <box size="0.4 0.4 0.075" />
      </geometry>
    </collision>
    <inertial>
      <mass value="0.15" />
      <inertia ixx="1" ixy="0" ixz="0" iyy="1" iyz="0" izz="1" />
    </inertial>
  </link>
  <joint name="act1Seg9_to_act1Seg10_ax1" type="revolute">
    <parent link="act1Seg9" />
    <child link="act1Seg10" />
    <origin xyz="0 0 0.15" rpy="0 0 0" />
    <axis xyz="0 1 0" />
    <limit lower="-3.141592" upper="3.141592" effort="100" velocity="3" />
  </joint>
  <link name="act1Seg10helper_shape">
    <visual>
      <origin xyz="0 0 0.0" rpy="-1.5707963267948966 0 0" />
      <geometry>
        <cylinder length="0.4" radius="0.2" />
      </geometry>
      <material name="blue">
        <color rgba="0.3 0.0 1 1.0" />
      </material>
    </visual>
    <collision>
      <origin xyz="0 0 0.0" rpy="-1.5707963267948966 0 0" />
      <geometry>
        <cylinder length="0.4" radius="0.2" />
      </geometry>
    </collision>
    <inertial>
      <mass value="0.00015" />
      <inertia ixx="0.001" ixy="0.0" ixz="0.0" iyy="0.001" iyz="0.0" izz="0.001" />
    </inertial>
  </link>
  <joint name="act1Seg9_to_act1Seg10_ax1helper_shape" type="fixed">
    <parent link="act1Seg9" />
    <child link="act1Seg10helper_shape" />
    <origin xyz="0 0 0.15" rpy="0 0 0" />
    <axis xyz="1 0 0" />
  </joint>
  <link name="act2Seg0">
    <visual>
      <origin xyz="0 0 0.0375" rpy="0 0 0" />
      <geometry>
        <box size="0.4 0.4 0.075" />
      </geometry>
      <material name="blue">
        <color rgba="0.3 0.0 1 1.0" />
      </material>
    </visual>
    <collision>
      <origin xyz="0 0 0.0375" rpy="0 0 0" />
      <geometry>
        <box size="0.4 0.4 0.075" />
      </geometry>
    </collision>
    <inertial>
      <mass value="0.15" />
      <inertia ixx="1" ixy="0" ixz="0" iyy="1" iyz="0" izz="1" />
    </inertial>
  </link>
  <joint name="act1Seg10_to_act2Seg0_ax1" type="fixed">
    <parent link="act1Seg10" />
    <child link="act2Seg0" />
    <origin xyz="0 0 0.075" rpy="0 0 0" />
    <axis xyz="0 1 0" />
    <limit lower="-3.141592" upper="3.141592" effort="100" velocity="3" />
  </joint>
  <link name="act2Seg1">
    <visual>
      <origin xyz="0 0 0.075" rpy="0 0 0" />
      <geometry>
        <box size="0.4 0.4 0.15" />
      </geometry>
      <material name="blue">
        <color rgba="0.3 0.0 1 1.0" />
      </material>
    </visual>
    <collision>
      <origin xyz="0 0 0.075" rpy="0 0 0" />
      <geometry>
        <box size="0.4 0.4 0.15" />
      </geometry>
    </collision>
    <inertial>
      <mass value="0.15" />
      <inertia ixx="1" ixy="0" ixz="0" iyy="1" iyz="0" izz="1" />
    </inertial>
  </link>
  <joint name="act2Seg0_to_act2Seg1_ax0" type="revolute">
    <parent link="act2Seg0" />
    <child link="act2Seg1" />
    <origin xyz="0 0 0.075" rpy="0 0 0" />
    <axis xyz="1 0 0" />
    <limit lower="-3.141592" upper="3.141592" effort="100" velocity="3" />
  </joint>
  <link name="act2Seg1helper_shape">
    <visual>
      <origin xyz="0 0 0.0" rpy="0 -1.5707963267948966 0" />
      <geometry>
        <cylinder length="0.4" radius="0.2" />
      </geometry>
      <material name="blue">
        <color rgba="0.3 0.0 1 1.0" />
      </material>
    </visual>
    <collision>
      <origin xyz="0 0 0.0" rpy="0 -1.5707963267948966 0" />
      <geometry>
        <cylinder length="0.4" radius="0.2" />
      </geometry>
    </collision>
    <inertial>
      <mass value="0.00015" />
      <inertia ixx="0.001" ixy="0.0" ixz="0.0" iyy="0.001" iyz="0.0" izz="0.001" />
    </inertial>
  </link>
  <joint name="act2Seg0_to_act2Seg1_ax0helper_shape" type="fixed">
    <parent link="act2Seg0" />
    <child link="act2Seg1helper_shape" />
    <origin xyz="0 0 0.075" rpy="0 0 0" />
    <axis xyz="1 0 0" />
  </joint>
  <link name="act2Seg2">
    <visual>
      <origin xyz="0 0 0.075" rpy="0 0 0" />
      <geometry>
        <box size="0.4 0.4 0.15" />
      </geometry>
      <material name="blue">
        <color rgba="0.3 0.0 1 1.0" />
      </material>
    </visual>
    <collision>
      <origin xyz="0 0 0.075" rpy="0 0 0" />
      <geometry>
        <box size="0.4 0.4 0.15" />
      </geometry>
    </collision>
    <inertial>
      <mass value="0.15" />
      <inertia ixx="1" ixy="0" ixz="0" iyy="1" iyz="0" izz="1" />
    </inertial>
  </link>
  <joint name="act2Seg1_to_act2Seg2_ax1" type="revolute">
    <parent link="act2Seg1" />
    <child link="act2Seg2" />
    <origin xyz="0 0 0.15" rpy="0 0 0" />
    <axis xyz="0 1 0" />
    <limit lower="-3.141592" upper="3.141592" effort="100" velocity="3" />
  </joint>
  <link name="act2Seg2helper_shape">
    <visual>
      <origin xyz="0 0 0.0" rpy="-1.5707963267948966 0 0" />
      <geometry>
        <cylinder length="0.4" radius="0.2" />
      </geometry>
      <material name="blue">
        <color rgba="0.3 0.0 1 1.0" />
      </material>
    </visual>
    <collision>
      <origin xyz="0 0 0.0" rpy="-1.5707963267948966 0 0" />
      <geometry>
        <cylinder length="0.4" radius="0.2" />
      </geometry>
    </collision>
    <inertial>
      <mass value="0.00015" />
      <inertia ixx="0.001" ixy="0.0" ixz="0.0" iyy="0.001" iyz="0.0" izz="0.001" />
    </inertial>
  </link>
  <joint name="act2Seg1_to_act2Seg2_ax1helper_shape" type="fixed">
    <parent link="act2Seg1" />
    <child link="act2Seg2helper_shape" />
    <origin xyz="0 0 0.15" rpy="0 0 0" />
    <axis xyz="1 0 0" />
  </joint>
  <link name="act2Seg3">
    <visual>
      <origin xyz="0 0 0.075" rpy="0 0 0" />
      <geometry>
        <box size="0.4 0.4 0.15" />
      </geometry>
      <material name="blue">
        <color rgba="0.3 0.0 1 1.0" />
      </material>
    </visual>
    <collision>
      <origin xyz="0 0 0.075" rpy="0 0 0" />
      <geometry>
        <box size="0.4 0.4 0.15" />
      </geometry>
    </collision>
    <inertial>
      <mass value="0.15" />
      <inertia ixx="1" ixy="0" ixz="0" iyy="1" iyz="0" izz="1" />
    </inertial>
  </link>
  <joint name="act2Seg2_to_act2Seg3_ax0" type="revolute">
    <parent link="act2Seg2" />
    <child link="act2Seg3" />
    <origin xyz="0 0 0.15" rpy="0 0 0" />
    <axis xyz="1 0 0" />
    <limit lower="-3.141592" upper="3.141592" effort="100" velocity="3" />
  </joint>
  <link name="act2Seg3helper_shape">
    <visual>
      <origin xyz="0 0 0.0" rpy="0 -1.5707963267948966 0" />
      <geometry>
        <cylinder length="0.4" radius="0.2" />
      </geometry>
      <material name="blue">
        <color rgba="0.3 0.0 1 1.0" />
      </material>
    </visual>
    <collision>
      <origin xyz="0 0 0.0" rpy="0 -1.5707963267948966 0" />
      <geometry>
        <cylinder length="0.4" radius="0.2" />
      </geometry>
    </collision>
    <inertial>
      <mass value="0.00015" />
      <inertia ixx="0.001" ixy="0.0" ixz="0.0" iyy="0.001" iyz="0.0" izz="0.001" />
    </inertial>
  </link>
  <joint name="act2Seg2_to_act2Seg3_ax0helper_shape" type="fixed">
    <parent link="act2Seg2" />
    <child link="act2Seg3helper_shape" />
    <origin xyz="0 0 0.15" rpy="0 0 0" />
    <axis xyz="1 0 0" />
  </joint>
  <link name="act2Seg4">
    <visual>
      <origin xyz="0 0 0.075" rpy="0 0 0" />
      <geometry>
        <box size="0.4 0.4 0.15" />
      </geometry>
      <material name="blue">
        <color rgba="0.3 0.0 1 1.0" />
      </material>
    </visual>
    <collision>
      <origin xyz="0 0 0.075" rpy="0 0 0" />
      <geometry>
        <box size="0.4 0.4 0.15" />
      </geometry>
    </collision>
    <inertial>
      <mass value="0.15" />
      <inertia ixx="1" ixy="0" ixz="0" iyy="1" iyz="0" izz="1" />
    </inertial>
  </link>
  <joint name="act2Seg3_to_act2Seg4_ax1" type="revolute">
    <parent link="act2Seg3" />
    <child link="act2Seg4" />
    <origin xyz="0 0 0.15" rpy="0 0 0" />
    <axis xyz="0 1 0" />
    <limit lower="-3.141592" upper="3.141592" effort="100" velocity="3" />
  </joint>
  <link name="act2Seg4helper_shape">
    <visual>
      <origin xyz="0 0 0.0" rpy="-1.5707963267948966 0 0" />
      <geometry>
        <cylinder length="0.4" radius="0.2" />
      </geometry>
      <material name="blue">
        <color rgba="0.3 0.0 1 1.0" />
      </material>
    </visual>
    <collision>
      <origin xyz="0 0 0.0" rpy="-1.5707963267948966 0 0" />
      <geometry>
        <cylinder length="0.4" radius="0.2" />
      </geometry>
    </collision>
    <inertial>
      <mass value="0.00015" />
      <inertia ixx="0.001" ixy="0.0" ixz="0.0" iyy="0.001" iyz="0.0" izz="0.001" />
    </inertial>
  </link>
  <joint name="act2Seg3_to_act2Seg4_ax1helper_shape" type="fixed">
    <parent link="act2Seg3" />
    <child link="act2Seg4helper_shape" />
    <origin xyz="0 0 0.15" rpy="0 0 0" />
    <axis xyz="1 0 0" />
  </joint>
  <link name="act2Seg5">
    <visual>
      <origin xyz="0 0 0.075" rpy="0 0 0" />
      <geometry>
        <box size="0.4 0.4 0.15" />
      </geometry>
      <material name="blue">
        <color rgba="0.3 0.0 1 1.0" />
      </material>
    </visual>
    <collision>
      <origin xyz="0 0 0.075" rpy="0 0 0" />
      <geometry>
        <box size="0.4 0.4 0.15" />
      </geometry>
    </collision>
    <inertial>
      <mass value="0.15" />
      <inertia ixx="1" ixy="0" ixz="0" iyy="1" iyz="0" izz="1" />
    </inertial>
  </link>
  <joint name="act2Seg4_to_act2Seg5_ax0" type="revolute">
    <parent link="act2Seg4" />
    <child link="act2Seg5" />
    <origin xyz="0 0 0.15" rpy="0 0 0" />
    <axis xyz="1 0 0" />
    <limit lower="-3.141592" upper="3.141592" effort="100" velocity="3" />
  </joint>
  <link name="act2Seg5helper_shape">
    <visual>
      <origin xyz="0 0 0.0" rpy="0 -1.5707963267948966 0" />
      <geometry>
        <cylinder length="0.4" radius="0.2" />
      </geometry>
      <material name="blue">
        <color rgba="0.3 0.0 1 1.0" />
      </material>
    </visual>
    <collision>
      <origin xyz="0 0 0.0" rpy="0 -1.5707963267948966 0" />
      <geometry>
        <cylinder length="0.4" radius="0.2" />
      </geometry>
    </collision>
    <inertial>
      <mass value="0.00015" />
      <inertia ixx="0.001" ixy="0.0" ixz="0.0" iyy="0.001" iyz="0.0" izz="0.001" />
    </inertial>
  </link>
  <joint name="act2Seg4_to_act2Seg5_ax0helper_shape" type="fixed">
    <parent link="act2Seg4" />
    <child link="act2Seg5helper_shape" />
    <origin xyz="0 0 0.15" rpy="0 0 0" />
    <axis xyz="1 0 0" />
  </joint>
  <link name="act2Seg6">
    <visual>
      <origin xyz="0 0 0.075" rpy="0 0 0" />
      <geometry>
        <box size="0.4 0.4 0.15" />
      </geometry>
      <material name="blue">
        <color rgba="0.3 0.0 1 1.0" />
      </material>
    </visual>
    <collision>
      <origin xyz="0 0 0.075" rpy="0 0 0" />
      <geometry>
        <box size="0.4 0.4 0.15" />
      </geometry>
    </collision>
    <inertial>
      <mass value="0.15" />
      <inertia ixx="1" ixy="0" ixz="0" iyy="1" iyz="0" izz="1" />
    </inertial>
  </link>
  <joint name="act2Seg5_to_act2Seg6_ax1" type="revolute">
    <parent link="act2Seg5" />
    <child link="act2Seg6" />
    <origin xyz="0 0 0.15" rpy="0 0 0" />
    <axis xyz="0 1 0" />
    <limit lower="-3.141592" upper="3.141592" effort="100" velocity="3" />
  </joint>
  <link name="act2Seg6helper_shape">
    <visual>
      <origin xyz="0 0 0.0" rpy="-1.5707963267948966 0 0" />
      <geometry>
        <cylinder length="0.4" radius="0.2" />
      </geometry>
      <material name="blue">
        <color rgba="0.3 0.0 1 1.0" />
      </material>
    </visual>
    <collision>
      <origin xyz="0 0 0.0" rpy="-1.5707963267948966 0 0" />
      <geometry>
        <cylinder length="0.4" radius="0.2" />
      </geometry>
    </collision>
    <inertial>
      <mass value="0.00015" />
      <inertia ixx="0.001" ixy="0.0" ixz="0.0" iyy="0.001" iyz="0.0" izz="0.001" />
    </inertial>
  </link>
  <joint name="act2Seg5_to_act2Seg6_ax1helper_shape" type="fixed">
    <parent link="act2Seg5" />
    <child link="act2Seg6helper_shape" />
    <origin xyz="0 0 0.15" rpy="0 0 0" />
    <axis xyz="1 0 0" />
  </joint>
  <link name="act2Seg7">
    <visual>
      <origin xyz="0 0 0.075" rpy="0 0 0" />
      <geometry>
        <box size="0.4 0.4 0.15" />
      </geometry>
      <material name="blue">
        <color rgba="0.3 0.0 1 1.0" />
      </material>
    </visual>
    <collision>
      <origin xyz="0 0 0.075" rpy="0 0 0" />
      <geometry>
        <box size="0.4 0.4 0.15" />
      </geometry>
    </collision>
    <inertial>
      <mass value="0.15" />
      <inertia ixx="1" ixy="0" ixz="0" iyy="1" iyz="0" izz="1" />
    </inertial>
  </link>
  <joint name="act2Seg6_to_act2Seg7_ax0" type="revolute">
    <parent link="act2Seg6" />
    <child link="act2Seg7" />
    <origin xyz="0 0 0.15" rpy="0 0 0" />
    <axis xyz="1 0 0" />
    <limit lower="-3.141592" upper="3.141592" effort="100" velocity="3" />
  </joint>
  <link name="act2Seg7helper_shape">
    <visual>
      <origin xyz="0 0 0.0" rpy="0 -1.5707963267948966 0" />
      <geometry>
        <cylinder length="0.4" radius="0.2" />
      </geometry>
      <material name="blue">
        <color rgba="0.3 0.0 1 1.0" />
      </material>
    </visual>
    <collision>
      <origin xyz="0 0 0.0" rpy="0 -1.5707963267948966 0" />
      <geometry>
        <cylinder length="0.4" radius="0.2" />
      </geometry>
    </collision>
    <inertial>
      <mass value="0.00015" />
      <inertia ixx="0.001" ixy="0.0" ixz="0.0" iyy="0.001" iyz="0.0" izz="0.001" />
    </inertial>
  </link>
  <joint name="act2Seg6_to_act2Seg7_ax0helper_shape" type="fixed">
    <parent link="act2Seg6" />
    <child link="act2Seg7helper_shape" />
    <origin xyz="0 0 0.15" rpy="0 0 0" />
    <axis xyz="1 0 0" />
  </joint>
  <link name="act2Seg8">
    <visual>
      <origin xyz="0 0 0.075" rpy="0 0 0" />
      <geometry>
        <box size="0.4 0.4 0.15" />
      </geometry>
      <material name="blue">
        <color rgba="0.3 0.0 1 1.0" />
      </material>
    </visual>
    <collision>
      <origin xyz="0 0 0.075" rpy="0 0 0" />
      <geometry>
        <box size="0.4 0.4 0.15" />
      </geometry>
    </collision>
    <inertial>
      <mass value="0.15" />
      <inertia ixx="1" ixy="0" ixz="0" iyy="1" iyz="0" izz="1" />
    </inertial>
  </link>
  <joint name="act2Seg7_to_act2Seg8_ax1" type="revolute">
    <parent link="act2Seg7" />
    <child link="act2Seg8" />
    <origin xyz="0 0 0.15" rpy="0 0 0" />
    <axis xyz="0 1 0" />
    <limit lower="-3.141592" upper="3.141592" effort="100" velocity="3" />
  </joint>
  <link name="act2Seg8helper_shape">
    <visual>
      <origin xyz="0 0 0.0" rpy="-1.5707963267948966 0 0" />
      <geometry>
        <cylinder length="0.4" radius="0.2" />
      </geometry>
      <material name="blue">
        <color rgba="0.3 0.0 1 1.0" />
      </material>
    </visual>
    <collision>
      <origin xyz="0 0 0.0" rpy="-1.5707963267948966 0 0" />
      <geometry>
        <cylinder length="0.4" radius="0.2" />
      </geometry>
    </collision>
    <inertial>
      <mass value="0.00015" />
      <inertia ixx="0.001" ixy="0.0" ixz="0.0" iyy="0.001" iyz="0.0" izz="0.001" />
    </inertial>
  </link>
  <joint name="act2Seg7_to_act2Seg8_ax1helper_shape" type="fixed">
    <parent link="act2Seg7" />
    <child link="act2Seg8helper_shape" />
    <origin xyz="0 0 0.15" rpy="0 0 0" />
    <axis xyz="1 0 0" />
  </joint>
  <link name="act2Seg9">
    <visual>
      <origin xyz="0 0 0.075" rpy="0 0 0" />
      <geometry>
        <box size="0.4 0.4 0.15" />
      </geometry>
      <material name="blue">
        <color rgba="0.3 0.0 1 1.0" />
      </material>
    </visual>
    <collision>
      <origin xyz="0 0 0.075" rpy="0 0 0" />
      <geometry>
        <box size="0.4 0.4 0.15" />
      </geometry>
    </collision>
    <inertial>
      <mass value="0.15" />
      <inertia ixx="1" ixy="0" ixz="0" iyy="1" iyz="0" izz="1" />
    </inertial>
  </link>
  <joint name="act2Seg8_to_act2Seg9_ax0" type="revolute">
    <parent link="act2Seg8" />
    <child link="act2Seg9" />
    <origin xyz="0 0 0.15" rpy="0 0 0" />
    <axis xyz="1 0 0" />
    <limit lower="-3.141592" upper="3.141592" effort="100" velocity="3" />
  </joint>
  <link name="act2Seg9helper_shape">
    <visual>
      <origin xyz="0 0 0.0" rpy="0 -1.5707963267948966 0" />
      <geometry>
        <cylinder length="0.4" radius="0.2" />
      </geometry>
      <material name="blue">
        <color rgba="0.3 0.0 1 1.0" />
      </material>
    </visual>
    <collision>
      <origin xyz="0 0 0.0" rpy="0 -1.5707963267948966 0" />
      <geometry>
        <cylinder length="0.4" radius="0.2" />
      </geometry>
    </collision>
    <inertial>
      <mass value="0.00015" />
      <inertia ixx="0.001" ixy="0.0" ixz="0.0" iyy="0.001" iyz="0.0" izz="0.001" />
    </inertial>
  </link>
  <joint name="act2Seg8_to_act2Seg9_ax0helper_shape" type="fixed">
    <parent link="act2Seg8" />
    <child link="act2Seg9helper_shape" />
    <origin xyz="0 0 0.15" rpy="0 0 0" />
    <axis xyz="1 0 0" />
  </joint>
  <link name="act2Seg10">
    <visual>
      <origin xyz="0 0 0.0375" rpy="0 0 0" />
      <geometry>
        <box size="0.4 0.4 0.075" />
      </geometry>
      <material name="blue">
        <color rgba="0.3 0.0 1 1.0" />
      </material>
    </visual>
    <collision>
      <origin xyz="0 0 0.0375" rpy="0 0 0" />
      <geometry>
        <box size="0.4 0.4 0.075" />
      </geometry>
    </collision>
    <inertial>
      <mass value="0.15" />
      <inertia ixx="1" ixy="0" ixz="0" iyy="1" iyz="0" izz="1" />
    </inertial>
  </link>
  <joint name="act2Seg9_to_act2Seg10_ax1" type="revolute">
    <parent link="act2Seg9" />
    <child link="act2Seg10" />
    <origin xyz="0 0 0.15" rpy="0 0 0" />
    <axis xyz="0 1 0" />
    <limit lower="-3.141592" upper="3.141592" effort="100" velocity="3" />
  </joint>
  <link name="act2Seg10helper_shape">
    <visual>
      <origin xyz="0 0 0.0" rpy="-1.5707963267948966 0 0" />
      <geometry>
        <cylinder length="0.4" radius="0.2" />
      </geometry>
      <material name="blue">
        <color rgba="0.3 0.0 1 1.0" />
      </material>
    </visual>
    <collision>
      <origin xyz="0 0 0.0" rpy="-1.5707963267948966 0 0" />
      <geometry>
        <cylinder length="0.4" radius="0.2" />
      </geometry>
    </collision>
    <inertial>
      <mass value="0.00015" />
      <inertia ixx="0.001" ixy="0.0" ixz="0.0" iyy="0.001" iyz="0.0" izz="0.001" />
    </inertial>
  </link>
  <joint name="act2Seg9_to_act2Seg10_ax1helper_shape" type="fixed">
    <parent link="act2Seg9" />
    <child link="act2Seg10helper_shape" />
    <origin xyz="0 0 0.15" rpy="0 0 0" />
    <axis xyz="1 0 0" />
  </joint>
  <link name="act3Seg0">
    <visual>
      <origin xyz="0 0 0.0375" rpy="0 0 0" />
      <geometry>
        <box size="0.4 0.4 0.075" />
      </geometry>
      <material name="blue">
        <color rgba="0.3 0.0 1 1.0" />
      </material>
    </visual>
    <collision>
      <origin xyz="0 0 0.0375" rpy="0 0 0" />
      <geometry>
        <box size="0.4 0.4 0.075" />
      </geometry>
    </collision>
    <inertial>
      <mass value="0.15" />
      <inertia ixx="1" ixy="0" ixz="0" iyy="1" iyz="0" izz="1" />
    </inertial>
  </link>
  <joint name="act2Seg10_to_act3Seg0_ax1" type="fixed">
    <parent link="act2Seg10" />
    <child link="act3Seg0" />
    <origin xyz="0 0 0.075" rpy="0 0 0" />
    <axis xyz="0 1 0" />
    <limit lower="-3.141592" upper="3.141592" effort="100" velocity="3" />
  </joint>
  <link name="act3Seg1">
    <visual>
      <origin xyz="0 0 0.075" rpy="0 0 0" />
      <geometry>
        <box size="0.4 0.4 0.15" />
      </geometry>
      <material name="blue">
        <color rgba="0.3 0.0 1 1.0" />
      </material>
    </visual>
    <collision>
      <origin xyz="0 0 0.075" rpy="0 0 0" />
      <geometry>
        <box size="0.4 0.4 0.15" />
      </geometry>
    </collision>
    <inertial>
      <mass value="0.15" />
      <inertia ixx="1" ixy="0" ixz="0" iyy="1" iyz="0" izz="1" />
    </inertial>
  </link>
  <joint name="act3Seg0_to_act3Seg1_ax0" type="revolute">
    <parent link="act3Seg0" />
    <child link="act3Seg1" />
    <origin xyz="0 0 0.075" rpy="0 0 0" />
    <axis xyz="1 0 0" />
    <limit lower="-3.141592" upper="3.141592" effort="100" velocity="3" />
  </joint>
  <link name="act3Seg1helper_shape">
    <visual>
      <origin xyz="0 0 0.0" rpy="0 -1.5707963267948966 0" />
      <geometry>
        <cylinder length="0.4" radius="0.2" />
      </geometry>
      <material name="blue">
        <color rgba="0.3 0.0 1 1.0" />
      </material>
    </visual>
    <collision>
      <origin xyz="0 0 0.0" rpy="0 -1.5707963267948966 0" />
      <geometry>
        <cylinder length="0.4" radius="0.2" />
      </geometry>
    </collision>
    <inertial>
      <mass value="0.00015" />
      <inertia ixx="0.001" ixy="0.0" ixz="0.0" iyy="0.001" iyz="0.0" izz="0.001" />
    </inertial>
  </link>
  <joint name="act3Seg0_to_act3Seg1_ax0helper_shape" type="fixed">
    <parent link="act3Seg0" />
    <child link="act3Seg1helper_shape" />
    <origin xyz="0 0 0.075" rpy="0 0 0" />
    <axis xyz="1 0 0" />
  </joint>
  <link name="act3Seg2">
    <visual>
      <origin xyz="0 0 0.075" rpy="0 0 0" />
      <geometry>
        <box size="0.4 0.4 0.15" />
      </geometry>
      <material name="blue">
        <color rgba="0.3 0.0 1 1.0" />
      </material>
    </visual>
    <collision>
      <origin xyz="0 0 0.075" rpy="0 0 0" />
      <geometry>
        <box size="0.4 0.4 0.15" />
      </geometry>
    </collision>
    <inertial>
      <mass value="0.15" />
      <inertia ixx="1" ixy="0" ixz="0" iyy="1" iyz="0" izz="1" />
    </inertial>
  </link>
  <joint name="act3Seg1_to_act3Seg2_ax1" type="revolute">
    <parent link="act3Seg1" />
    <child link="act3Seg2" />
    <origin xyz="0 0 0.15" rpy="0 0 0" />
    <axis xyz="0 1 0" />
    <limit lower="-3.141592" upper="3.141592" effort="100" velocity="3" />
  </joint>
  <link name="act3Seg2helper_shape">
    <visual>
      <origin xyz="0 0 0.0" rpy="-1.5707963267948966 0 0" />
      <geometry>
        <cylinder length="0.4" radius="0.2" />
      </geometry>
      <material name="blue">
        <color rgba="0.3 0.0 1 1.0" />
      </material>
    </visual>
    <collision>
      <origin xyz="0 0 0.0" rpy="-1.5707963267948966 0 0" />
      <geometry>
        <cylinder length="0.4" radius="0.2" />
      </geometry>
    </collision>
    <inertial>
      <mass value="0.00015" />
      <inertia ixx="0.001" ixy="0.0" ixz="0.0" iyy="0.001" iyz="0.0" izz="0.001" />
    </inertial>
  </link>
  <joint name="act3Seg1_to_act3Seg2_ax1helper_shape" type="fixed">
    <parent link="act3Seg1" />
    <child link="act3Seg2helper_shape" />
    <origin xyz="0 0 0.15" rpy="0 0 0" />
    <axis xyz="1 0 0" />
  </joint>
  <link name="act3Seg3">
    <visual>
      <origin xyz="0 0 0.075" rpy="0 0 0" />
      <geometry>
        <box size="0.4 0.4 0.15" />
      </geometry>
      <material name="blue">
        <color rgba="0.3 0.0 1 1.0" />
      </material>
    </visual>
    <collision>
      <origin xyz="0 0 0.075" rpy="0 0 0" />
      <geometry>
        <box size="0.4 0.4 0.15" />
      </geometry>
    </collision>
    <inertial>
      <mass value="0.15" />
      <inertia ixx="1" ixy="0" ixz="0" iyy="1" iyz="0" izz="1" />
    </inertial>
  </link>
  <joint name="act3Seg2_to_act3Seg3_ax0" type="revolute">
    <parent link="act3Seg2" />
    <child link="act3Seg3" />
    <origin xyz="0 0 0.15" rpy="0 0 0" />
    <axis xyz="1 0 0" />
    <limit lower="-3.141592" upper="3.141592" effort="100" velocity="3" />
  </joint>
  <link name="act3Seg3helper_shape">
    <visual>
      <origin xyz="0 0 0.0" rpy="0 -1.5707963267948966 0" />
      <geometry>
        <cylinder length="0.4" radius="0.2" />
      </geometry>
      <material name="blue">
        <color rgba="0.3 0.0 1 1.0" />
      </material>
    </visual>
    <collision>
      <origin xyz="0 0 0.0" rpy="0 -1.5707963267948966 0" />
      <geometry>
        <cylinder length="0.4" radius="0.2" />
      </geometry>
    </collision>
    <inertial>
      <mass value="0.00015" />
      <inertia ixx="0.001" ixy="0.0" ixz="0.0" iyy="0.001" iyz="0.0" izz="0.001" />
    </inertial>
  </link>
  <joint name="act3Seg2_to_act3Seg3_ax0helper_shape" type="fixed">
    <parent link="act3Seg2" />
    <child link="act3Seg3helper_shape" />
    <origin xyz="0 0 0.15" rpy="0 0 0" />
    <axis xyz="1 0 0" />
  </joint>
  <link name="act3Seg4">
    <visual>
      <origin xyz="0 0 0.075" rpy="0 0 0" />
      <geometry>
        <box size="0.4 0.4 0.15" />
      </geometry>
      <material name="blue">
        <color rgba="0.3 0.0 1 1.0" />
      </material>
    </visual>
    <collision>
      <origin xyz="0 0 0.075" rpy="0 0 0" />
      <geometry>
        <box size="0.4 0.4 0.15" />
      </geometry>
    </collision>
    <inertial>
      <mass value="0.15" />
      <inertia ixx="1" ixy="0" ixz="0" iyy="1" iyz="0" izz="1" />
    </inertial>
  </link>
  <joint name="act3Seg3_to_act3Seg4_ax1" type="revolute">
    <parent link="act3Seg3" />
    <child link="act3Seg4" />
    <origin xyz="0 0 0.15" rpy="0 0 0" />
    <axis xyz="0 1 0" />
    <limit lower="-3.141592" upper="3.141592" effort="100" velocity="3" />
  </joint>
  <link name="act3Seg4helper_shape">
    <visual>
      <origin xyz="0 0 0.0" rpy="-1.5707963267948966 0 0" />
      <geometry>
        <cylinder length="0.4" radius="0.2" />
      </geometry>
      <material name="blue">
        <color rgba="0.3 0.0 1 1.0" />
      </material>
    </visual>
    <collision>
      <origin xyz="0 0 0.0" rpy="-1.5707963267948966 0 0" />
      <geometry>
        <cylinder length="0.4" radius="0.2" />
      </geometry>
    </collision>
    <inertial>
      <mass value="0.00015" />
      <inertia ixx="0.001" ixy="0.0" ixz="0.0" iyy="0.001" iyz="0.0" izz="0.001" />
    </inertial>
  </link>
  <joint name="act3Seg3_to_act3Seg4_ax1helper_shape" type="fixed">
    <parent link="act3Seg3" />
    <child link="act3Seg4helper_shape" />
    <origin xyz="0 0 0.15" rpy="0 0 0" />
    <axis xyz="1 0 0" />
  </joint>
  <link name="act3Seg5">
    <visual>
      <origin xyz="0 0 0.075" rpy="0 0 0" />
      <geometry>
        <box size="0.4 0.4 0.15" />
      </geometry>
      <material name="blue">
        <color rgba="0.3 0.0 1 1.0" />
      </material>
    </visual>
    <collision>
      <origin xyz="0 0 0.075" rpy="0 0 0" />
      <geometry>
        <box size="0.4 0.4 0.15" />
      </geometry>
    </collision>
    <inertial>
      <mass value="0.15" />
      <inertia ixx="1" ixy="0" ixz="0" iyy="1" iyz="0" izz="1" />
    </inertial>
  </link>
  <joint name="act3Seg4_to_act3Seg5_ax0" type="revolute">
    <parent link="act3Seg4" />
    <child link="act3Seg5" />
    <origin xyz="0 0 0.15" rpy="0 0 0" />
    <axis xyz="1 0 0" />
    <limit lower="-3.141592" upper="3.141592" effort="100" velocity="3" />
  </joint>
  <link name="act3Seg5helper_shape">
    <visual>
      <origin xyz="0 0 0.0" rpy="0 -1.5707963267948966 0" />
      <geometry>
        <cylinder length="0.4" radius="0.2" />
      </geometry>
      <material name="blue">
        <color rgba="0.3 0.0 1 1.0" />
      </material>
    </visual>
    <collision>
      <origin xyz="0 0 0.0" rpy="0 -1.5707963267948966 0" />
      <geometry>
        <cylinder length="0.4" radius="0.2" />
      </geometry>
    </collision>
    <inertial>
      <mass value="0.00015" />
      <inertia ixx="0.001" ixy="0.0" ixz="0.0" iyy="0.001" iyz="0.0" izz="0.001" />
    </inertial>
  </link>
  <joint name="act3Seg4_to_act3Seg5_ax0helper_shape" type="fixed">
    <parent link="act3Seg4" />
    <child link="act3Seg5helper_shape" />
    <origin xyz="0 0 0.15" rpy="0 0 0" />
    <axis xyz="1 0 0" />
  </joint>
  <link name="act3Seg6">
    <visual>
      <origin xyz="0 0 0.075" rpy="0 0 0" />
      <geometry>
        <box size="0.4 0.4 0.15" />
      </geometry>
      <material name="blue">
        <color rgba="0.3 0.0 1 1.0" />
      </material>
    </visual>
    <collision>
      <origin xyz="0 0 0.075" rpy="0 0 0" />
      <geometry>
        <box size="0.4 0.4 0.15" />
      </geometry>
    </collision>
    <inertial>
      <mass value="0.15" />
      <inertia ixx="1" ixy="0" ixz="0" iyy="1" iyz="0" izz="1" />
    </inertial>
  </link>
  <joint name="act3Seg5_to_act3Seg6_ax1" type="revolute">
    <parent link="act3Seg5" />
    <child link="act3Seg6" />
    <origin xyz="0 0 0.15" rpy="0 0 0" />
    <axis xyz="0 1 0" />
    <limit lower="-3.141592" upper="3.141592" effort="100" velocity="3" />
  </joint>
  <link name="act3Seg6helper_shape">
    <visual>
      <origin xyz="0 0 0.0" rpy="-1.5707963267948966 0 0" />
      <geometry>
        <cylinder length="0.4" radius="0.2" />
      </geometry>
      <material name="blue">
        <color rgba="0.3 0.0 1 1.0" />
      </material>
    </visual>
    <collision>
      <origin xyz="0 0 0.0" rpy="-1.5707963267948966 0 0" />
      <geometry>
        <cylinder length="0.4" radius="0.2" />
      </geometry>
    </collision>
    <inertial>
      <mass value="0.00015" />
      <inertia ixx="0.001" ixy="0.0" ixz="0.0" iyy="0.001" iyz="0.0" izz="0.001" />
    </inertial>
  </link>
  <joint name="act3Seg5_to_act3Seg6_ax1helper_shape" type="fixed">
    <parent link="act3Seg5" />
    <child link="act3Seg6helper_shape" />
    <origin xyz="0 0 0.15" rpy="0 0 0" />
    <axis xyz="1 0 0" />
  </joint>
  <link name="act3Seg7">
    <visual>
      <origin xyz="0 0 0.075" rpy="0 0 0" />
      <geometry>
        <box size="0.4 0.4 0.15" />
      </geometry>
      <material name="blue">
        <color rgba="0.3 0.0 1 1.0" />
      </material>
    </visual>
    <collision>
      <origin xyz="0 0 0.075" rpy="0 0 0" />
      <geometry>
        <box size="0.4 0.4 0.15" />
      </geometry>
    </collision>
    <inertial>
      <mass value="0.15" />
      <inertia ixx="1" ixy="0" ixz="0" iyy="1" iyz="0" izz="1" />
    </inertial>
  </link>
  <joint name="act3Seg6_to_act3Seg7_ax0" type="revolute">
    <parent link="act3Seg6" />
    <child link="act3Seg7" />
    <origin xyz="0 0 0.15" rpy="0 0 0" />
    <axis xyz="1 0 0" />
    <limit lower="-3.141592" upper="3.141592" effort="100" velocity="3" />
  </joint>
  <link name="act3Seg7helper_shape">
    <visual>
      <origin xyz="0 0 0.0" rpy="0 -1.5707963267948966 0" />
      <geometry>
        <cylinder length="0.4" radius="0.2" />
      </geometry>
      <material name="blue">
        <color rgba="0.3 0.0 1 1.0" />
      </material>
    </visual>
    <collision>
      <origin xyz="0 0 0.0" rpy="0 -1.5707963267948966 0" />
      <geometry>
        <cylinder length="0.4" radius="0.2" />
      </geometry>
    </collision>
    <inertial>
      <mass value="0.00015" />
      <inertia ixx="0.001" ixy="0.0" ixz="0.0" iyy="0.001" iyz="0.0" izz="0.001" />
    </inertial>
  </link>
  <joint name="act3Seg6_to_act3Seg7_ax0helper_shape" type="fixed">
    <parent link="act3Seg6" />
    <child link="act3Seg7helper_shape" />
    <origin xyz="0 0 0.15" rpy="0 0 0" />
    <axis xyz="1 0 0" />
  </joint>
  <link name="act3Seg8">
    <visual>
      <origin xyz="0 0 0.075" rpy="0 0 0" />
      <geometry>
        <box size="0.4 0.4 0.15" />
      </geometry>
      <material name="blue">
        <color rgba="0.3 0.0 1 1.0" />
      </material>
    </visual>
    <collision>
      <origin xyz="0 0 0.075" rpy="0 0 0" />
      <geometry>
        <box size="0.4 0.4 0.15" />
      </geometry>
    </collision>
    <inertial>
      <mass value="0.15" />
      <inertia ixx="1" ixy="0" ixz="0" iyy="1" iyz="0" izz="1" />
    </inertial>
  </link>
  <joint name="act3Seg7_to_act3Seg8_ax1" type="revolute">
    <parent link="act3Seg7" />
    <child link="act3Seg8" />
    <origin xyz="0 0 0.15" rpy="0 0 0" />
    <axis xyz="0 1 0" />
    <limit lower="-3.141592" upper="3.141592" effort="100" velocity="3" />
  </joint>
  <link name="act3Seg8helper_shape">
    <visual>
      <origin xyz="0 0 0.0" rpy="-1.5707963267948966 0 0" />
      <geometry>
        <cylinder length="0.4" radius="0.2" />
      </geometry>
      <material name="blue">
        <color rgba="0.3 0.0 1 1.0" />
      </material>
    </visual>
    <collision>
      <origin xyz="0 0 0.0" rpy="-1.5707963267948966 0 0" />
      <geometry>
        <cylinder length="0.4" radius="0.2" />
      </geometry>
    </collision>
    <inertial>
      <mass value="0.00015" />
      <inertia ixx="0.001" ixy="0.0" ixz="0.0" iyy="0.001" iyz="0.0" izz="0.001" />
    </inertial>
  </link>
  <joint name="act3Seg7_to_act3Seg8_ax1helper_shape" type="fixed">
    <parent link="act3Seg7" />
    <child link="act3Seg8helper_shape" />
    <origin xyz="0 0 0.15" rpy="0 0 0" />
    <axis xyz="1 0 0" />
  </joint>
  <link name="act3Seg9">
    <visual>
      <origin xyz="0 0 0.075" rpy="0 0 0" />
      <geometry>
        <box size="0.4 0.4 0.15" />
      </geometry>
      <material name="blue">
        <color rgba="0.3 0.0 1 1.0" />
      </material>
    </visual>
    <collision>
      <origin xyz="0 0 0.075" rpy="0 0 0" />
      <geometry>
        <box size="0.4 0.4 0.15" />
      </geometry>
    </collision>
    <inertial>
      <mass value="0.15" />
      <inertia ixx="1" ixy="0" ixz="0" iyy="1" iyz="0" izz="1" />
    </inertial>
  </link>
  <joint name="act3Seg8_to_act3Seg9_ax0" type="revolute">
    <parent link="act3Seg8" />
    <child link="act3Seg9" />
    <origin xyz="0 0 0.15" rpy="0 0 0" />
    <axis xyz="1 0 0" />
    <limit lower="-3.141592" upper="3.141592" effort="100" velocity="3" />
  </joint>
  <link name="act3Seg9helper_shape">
    <visual>
      <origin xyz="0 0 0.0" rpy="0 -1.5707963267948966 0" />
      <geometry>
        <cylinder length="0.4" radius="0.2" />
      </geometry>
      <material name="blue">
        <color rgba="0.3 0.0 1 1.0" />
      </material>
    </visual>
    <collision>
      <origin xyz="0 0 0.0" rpy="0 -1.5707963267948966 0" />
      <geometry>
        <cylinder length="0.4" radius="0.2" />
      </geometry>
    </collision>
    <inertial>
      <mass value="0.00015" />
      <inertia ixx="0.001" ixy="0.0" ixz="0.0" iyy="0.001" iyz="0.0" izz="0.001" />
    </inertial>
  </link>
  <joint name="act3Seg8_to_act3Seg9_ax0helper_shape" type="fixed">
    <parent link="act3Seg8" />
    <child link="act3Seg9helper_shape" />
    <origin xyz="0 0 0.15" rpy="0 0 0" />
    <axis xyz="1 0 0" />
  </joint>
  <link name="act3Seg10">
    <visual>
      <origin xyz="0 0 0.0375" rpy="0 0 0" />
      <geometry>
        <box size="0.4 0.4 0.075" />
      </geometry>
      <material name="blue">
        <color rgba="0.3 0.0 1 1.0" />
      </material>
    </visual>
    <collision>
      <origin xyz="0 0 0.0375" rpy="0 0 0" />
      <geometry>
        <box size="0.4 0.4 0.075" />
      </geometry>
    </collision>
    <inertial>
      <mass value="0.15" />
      <inertia ixx="1" ixy="0" ixz="0" iyy="1" iyz="0" izz="1" />
    </inertial>
  </link>
  <joint name="act3Seg9_to_act3Seg10_ax1" type="revolute">
    <parent link="act3Seg9" />
    <child link="act3Seg10" />
    <origin xyz="0 0 0.15" rpy="0 0 0" />
    <axis xyz="0 1 0" />
    <limit lower="-3.141592" upper="3.141592" effort="100" velocity="3" />
  </joint>
  <link name="act3Seg10helper_shape">
    <visual>
      <origin xyz="0 0 0.0" rpy="-1.5707963267948966 0 0" />
      <geometry>
        <cylinder length="0.4" radius="0.2" />
      </geometry>
      <material name="blue">
        <color rgba="0.3 0.0 1 1.0" />
      </material>
    </visual>
    <collision>
      <origin xyz="0 0 0.0" rpy="-1.5707963267948966 0 0" />
      <geometry>
        <cylinder length="0.4" radius="0.2" />
      </geometry>
    </collision>
    <inertial>
      <mass value="0.00015" />
      <inertia ixx="0.001" ixy="0.0" ixz="0.0" iyy="0.001" iyz="0.0" izz="0.001" />
    </inertial>
  </link>
  <joint name="act3Seg9_to_act3Seg10_ax1helper_shape" type="fixed">
    <parent link="act3Seg9" />
    <child link="act3Seg10helper_shape" />
    <origin xyz="0 0 0.15" rpy="0 0 0" />
    <axis xyz="1 0 0" />
  </joint>
  <link name="act4Seg0">
    <visual>
      <origin xyz="0 0 0.0375" rpy="0 0 0" />
      <geometry>
        <box size="0.4 0.4 0.075" />
      </geometry>
      <material name="blue">
        <color rgba="0.3 0.0 1 1.0" />
      </material>
    </visual>
    <collision>
      <origin xyz="0 0 0.0375" rpy="0 0 0" />
      <geometry>
        <box size="0.4 0.4 0.075" />
      </geometry>
    </collision>
    <inertial>
      <mass value="0.15" />
      <inertia ixx="1" ixy="0" ixz="0" iyy="1" iyz="0" izz="1" />
    </inertial>
  </link>
  <joint name="act3Seg10_to_act4Seg0_ax1" type="fixed">
    <parent link="act3Seg10" />
    <child link="act4Seg0" />
    <origin xyz="0 0 0.075" rpy="0 0 0" />
    <axis xyz="0 1 0" />
    <limit lower="-3.141592" upper="3.141592" effort="100" velocity="3" />
  </joint>
  <link name="act4Seg1">
    <visual>
      <origin xyz="0 0 0.075" rpy="0 0 0" />
      <geometry>
        <box size="0.4 0.4 0.15" />
      </geometry>
      <material name="blue">
        <color rgba="0.3 0.0 1 1.0" />
      </material>
    </visual>
    <collision>
      <origin xyz="0 0 0.075" rpy="0 0 0" />
      <geometry>
        <box size="0.4 0.4 0.15" />
      </geometry>
    </collision>
    <inertial>
      <mass value="0.15" />
      <inertia ixx="1" ixy="0" ixz="0" iyy="1" iyz="0" izz="1" />
    </inertial>
  </link>
  <joint name="act4Seg0_to_act4Seg1_ax0" type="revolute">
    <parent link="act4Seg0" />
    <child link="act4Seg1" />
    <origin xyz="0 0 0.075" rpy="0 0 0" />
    <axis xyz="1 0 0" />
    <limit lower="-3.141592" upper="3.141592" effort="100" velocity="3" />
  </joint>
  <link name="act4Seg1helper_shape">
    <visual>
      <origin xyz="0 0 0.0" rpy="0 -1.5707963267948966 0" />
      <geometry>
        <cylinder length="0.4" radius="0.2" />
      </geometry>
      <material name="blue">
        <color rgba="0.3 0.0 1 1.0" />
      </material>
    </visual>
    <collision>
      <origin xyz="0 0 0.0" rpy="0 -1.5707963267948966 0" />
      <geometry>
        <cylinder length="0.4" radius="0.2" />
      </geometry>
    </collision>
    <inertial>
      <mass value="0.00015" />
      <inertia ixx="0.001" ixy="0.0" ixz="0.0" iyy="0.001" iyz="0.0" izz="0.001" />
    </inertial>
  </link>
  <joint name="act4Seg0_to_act4Seg1_ax0helper_shape" type="fixed">
    <parent link="act4Seg0" />
    <child link="act4Seg1helper_shape" />
    <origin xyz="0 0 0.075" rpy="0 0 0" />
    <axis xyz="1 0 0" />
  </joint>
  <link name="act4Seg2">
    <visual>
      <origin xyz="0 0 0.075" rpy="0 0 0" />
      <geometry>
        <box size="0.4 0.4 0.15" />
      </geometry>
      <material name="blue">
        <color rgba="0.3 0.0 1 1.0" />
      </material>
    </visual>
    <collision>
      <origin xyz="0 0 0.075" rpy="0 0 0" />
      <geometry>
        <box size="0.4 0.4 0.15" />
      </geometry>
    </collision>
    <inertial>
      <mass value="0.15" />
      <inertia ixx="1" ixy="0" ixz="0" iyy="1" iyz="0" izz="1" />
    </inertial>
  </link>
  <joint name="act4Seg1_to_act4Seg2_ax1" type="revolute">
    <parent link="act4Seg1" />
    <child link="act4Seg2" />
    <origin xyz="0 0 0.15" rpy="0 0 0" />
    <axis xyz="0 1 0" />
    <limit lower="-3.141592" upper="3.141592" effort="100" velocity="3" />
  </joint>
  <link name="act4Seg2helper_shape">
    <visual>
      <origin xyz="0 0 0.0" rpy="-1.5707963267948966 0 0" />
      <geometry>
        <cylinder length="0.4" radius="0.2" />
      </geometry>
      <material name="blue">
        <color rgba="0.3 0.0 1 1.0" />
      </material>
    </visual>
    <collision>
      <origin xyz="0 0 0.0" rpy="-1.5707963267948966 0 0" />
      <geometry>
        <cylinder length="0.4" radius="0.2" />
      </geometry>
    </collision>
    <inertial>
      <mass value="0.00015" />
      <inertia ixx="0.001" ixy="0.0" ixz="0.0" iyy="0.001" iyz="0.0" izz="0.001" />
    </inertial>
  </link>
  <joint name="act4Seg1_to_act4Seg2_ax1helper_shape" type="fixed">
    <parent link="act4Seg1" />
    <child link="act4Seg2helper_shape" />
    <origin xyz="0 0 0.15" rpy="0 0 0" />
    <axis xyz="1 0 0" />
  </joint>
  <link name="act4Seg3">
    <visual>
      <origin xyz="0 0 0.075" rpy="0 0 0" />
      <geometry>
        <box size="0.4 0.4 0.15" />
      </geometry>
      <material name="blue">
        <color rgba="0.3 0.0 1 1.0" />
      </material>
    </visual>
    <collision>
      <origin xyz="0 0 0.075" rpy="0 0 0" />
      <geometry>
        <box size="0.4 0.4 0.15" />
      </geometry>
    </collision>
    <inertial>
      <mass value="0.15" />
      <inertia ixx="1" ixy="0" ixz="0" iyy="1" iyz="0" izz="1" />
    </inertial>
  </link>
  <joint name="act4Seg2_to_act4Seg3_ax0" type="revolute">
    <parent link="act4Seg2" />
    <child link="act4Seg3" />
    <origin xyz="0 0 0.15" rpy="0 0 0" />
    <axis xyz="1 0 0" />
    <limit lower="-3.141592" upper="3.141592" effort="100" velocity="3" />
  </joint>
  <link name="act4Seg3helper_shape">
    <visual>
      <origin xyz="0 0 0.0" rpy="0 -1.5707963267948966 0" />
      <geometry>
        <cylinder length="0.4" radius="0.2" />
      </geometry>
      <material name="blue">
        <color rgba="0.3 0.0 1 1.0" />
      </material>
    </visual>
    <collision>
      <origin xyz="0 0 0.0" rpy="0 -1.5707963267948966 0" />
      <geometry>
        <cylinder length="0.4" radius="0.2" />
      </geometry>
    </collision>
    <inertial>
      <mass value="0.00015" />
      <inertia ixx="0.001" ixy="0.0" ixz="0.0" iyy="0.001" iyz="0.0" izz="0.001" />
    </inertial>
  </link>
  <joint name="act4Seg2_to_act4Seg3_ax0helper_shape" type="fixed">
    <parent link="act4Seg2" />
    <child link="act4Seg3helper_shape" />
    <origin xyz="0 0 0.15" rpy="0 0 0" />
    <axis xyz="1 0 0" />
  </joint>
  <link name="act4Seg4">
    <visual>
      <origin xyz="0 0 0.075" rpy="0 0 0" />
      <geometry>
        <box size="0.4 0.4 0.15" />
      </geometry>
      <material name="blue">
        <color rgba="0.3 0.0 1 1.0" />
      </material>
    </visual>
    <collision>
      <origin xyz="0 0 0.075" rpy="0 0 0" />
      <geometry>
        <box size="0.4 0.4 0.15" />
      </geometry>
    </collision>
    <inertial>
      <mass value="0.15" />
      <inertia ixx="1" ixy="0" ixz="0" iyy="1" iyz="0" izz="1" />
    </inertial>
  </link>
  <joint name="act4Seg3_to_act4Seg4_ax1" type="revolute">
    <parent link="act4Seg3" />
    <child link="act4Seg4" />
    <origin xyz="0 0 0.15" rpy="0 0 0" />
    <axis xyz="0 1 0" />
    <limit lower="-3.141592" upper="3.141592" effort="100" velocity="3" />
  </joint>
  <link name="act4Seg4helper_shape">
    <visual>
      <origin xyz="0 0 0.0" rpy="-1.5707963267948966 0 0" />
      <geometry>
        <cylinder length="0.4" radius="0.2" />
      </geometry>
      <material name="blue">
        <color rgba="0.3 0.0 1 1.0" />
      </material>
    </visual>
    <collision>
      <origin xyz="0 0 0.0" rpy="-1.5707963267948966 0 0" />
      <geometry>
        <cylinder length="0.4" radius="0.2" />
      </geometry>
    </collision>
    <inertial>
      <mass value="0.00015" />
      <inertia ixx="0.001" ixy="0.0" ixz="0.0" iyy="0.001" iyz="0.0" izz="0.001" />
    </inertial>
  </link>
  <joint name="act4Seg3_to_act4Seg4_ax1helper_shape" type="fixed">
    <parent link="act4Seg3" />
    <child link="act4Seg4helper_shape" />
    <origin xyz="0 0 0.15" rpy="0 0 0" />
    <axis xyz="1 0 0" />
  </joint>
  <link name="act4Seg5">
    <visual>
      <origin xyz="0 0 0.075" rpy="0 0 0" />
      <geometry>
        <box size="0.4 0.4 0.15" />
      </geometry>
      <material name="blue">
        <color rgba="0.3 0.0 1 1.0" />
      </material>
    </visual>
    <collision>
      <origin xyz="0 0 0.075" rpy="0 0 0" />
      <geometry>
        <box size="0.4 0.4 0.15" />
      </geometry>
    </collision>
    <inertial>
      <mass value="0.15" />
      <inertia ixx="1" ixy="0" ixz="0" iyy="1" iyz="0" izz="1" />
    </inertial>
  </link>
  <joint name="act4Seg4_to_act4Seg5_ax0" type="revolute">
    <parent link="act4Seg4" />
    <child link="act4Seg5" />
    <origin xyz="0 0 0.15" rpy="0 0 0" />
    <axis xyz="1 0 0" />
    <limit lower="-3.141592" upper="3.141592" effort="100" velocity="3" />
  </joint>
  <link name="act4Seg5helper_shape">
    <visual>
      <origin xyz="0 0 0.0" rpy="0 -1.5707963267948966 0" />
      <geometry>
        <cylinder length="0.4" radius="0.2" />
      </geometry>
      <material name="blue">
        <color rgba="0.3 0.0 1 1.0" />
      </material>
    </visual>
    <collision>
      <origin xyz="0 0 0.0" rpy="0 -1.5707963267948966 0" />
      <geometry>
        <cylinder length="0.4" radius="0.2" />
      </geometry>
    </collision>
    <inertial>
      <mass value="0.00015" />
      <inertia ixx="0.001" ixy="0.0" ixz="0.0" iyy="0.001" iyz="0.0" izz="0.001" />
    </inertial>
  </link>
  <joint name="act4Seg4_to_act4Seg5_ax0helper_shape" type="fixed">
    <parent link="act4Seg4" />
    <child link="act4Seg5helper_shape" />
    <origin xyz="0 0 0.15" rpy="0 0 0" />
    <axis xyz="1 0 0" />
  </joint>
  <link name="act4Seg6">
    <visual>
      <origin xyz="0 0 0.075" rpy="0 0 0" />
      <geometry>
        <box size="0.4 0.4 0.15" />
      </geometry>
      <material name="blue">
        <color rgba="0.3 0.0 1 1.0" />
      </material>
    </visual>
    <collision>
      <origin xyz="0 0 0.075" rpy="0 0 0" />
      <geometry>
        <box size="0.4 0.4 0.15" />
      </geometry>
    </collision>
    <inertial>
      <mass value="0.15" />
      <inertia ixx="1" ixy="0" ixz="0" iyy="1" iyz="0" izz="1" />
    </inertial>
  </link>
  <joint name="act4Seg5_to_act4Seg6_ax1" type="revolute">
    <parent link="act4Seg5" />
    <child link="act4Seg6" />
    <origin xyz="0 0 0.15" rpy="0 0 0" />
    <axis xyz="0 1 0" />
    <limit lower="-3.141592" upper="3.141592" effort="100" velocity="3" />
  </joint>
  <link name="act4Seg6helper_shape">
    <visual>
      <origin xyz="0 0 0.0" rpy="-1.5707963267948966 0 0" />
      <geometry>
        <cylinder length="0.4" radius="0.2" />
      </geometry>
      <material name="blue">
        <color rgba="0.3 0.0 1 1.0" />
      </material>
    </visual>
    <collision>
      <origin xyz="0 0 0.0" rpy="-1.5707963267948966 0 0" />
      <geometry>
        <cylinder length="0.4" radius="0.2" />
      </geometry>
    </collision>
    <inertial>
      <mass value="0.00015" />
      <inertia ixx="0.001" ixy="0.0" ixz="0.0" iyy="0.001" iyz="0.0" izz="0.001" />
    </inertial>
  </link>
  <joint name="act4Seg5_to_act4Seg6_ax1helper_shape" type="fixed">
    <parent link="act4Seg5" />
    <child link="act4Seg6helper_shape" />
    <origin xyz="0 0 0.15" rpy="0 0 0" />
    <axis xyz="1 0 0" />
  </joint>
  <link name="act4Seg7">
    <visual>
      <origin xyz="0 0 0.075" rpy="0 0 0" />
      <geometry>
        <box size="0.4 0.4 0.15" />
      </geometry>
      <material name="blue">
        <color rgba="0.3 0.0 1 1.0" />
      </material>
    </visual>
    <collision>
      <origin xyz="0 0 0.075" rpy="0 0 0" />
      <geometry>
        <box size="0.4 0.4 0.15" />
      </geometry>
    </collision>
    <inertial>
      <mass value="0.15" />
      <inertia ixx="1" ixy="0" ixz="0" iyy="1" iyz="0" izz="1" />
    </inertial>
  </link>
  <joint name="act4Seg6_to_act4Seg7_ax0" type="revolute">
    <parent link="act4Seg6" />
    <child link="act4Seg7" />
    <origin xyz="0 0 0.15" rpy="0 0 0" />
    <axis xyz="1 0 0" />
    <limit lower="-3.141592" upper="3.141592" effort="100" velocity="3" />
  </joint>
  <link name="act4Seg7helper_shape">
    <visual>
      <origin xyz="0 0 0.0" rpy="0 -1.5707963267948966 0" />
      <geometry>
        <cylinder length="0.4" radius="0.2" />
      </geometry>
      <material name="blue">
        <color rgba="0.3 0.0 1 1.0" />
      </material>
    </visual>
    <collision>
      <origin xyz="0 0 0.0" rpy="0 -1.5707963267948966 0" />
      <geometry>
        <cylinder length="0.4" radius="0.2" />
      </geometry>
    </collision>
    <inertial>
      <mass value="0.00015" />
      <inertia ixx="0.001" ixy="0.0" ixz="0.0" iyy="0.001" iyz="0.0" izz="0.001" />
    </inertial>
  </link>
  <joint name="act4Seg6_to_act4Seg7_ax0helper_shape" type="fixed">
    <parent link="act4Seg6" />
    <child link="act4Seg7helper_shape" />
    <origin xyz="0 0 0.15" rpy="0 0 0" />
    <axis xyz="1 0 0" />
  </joint>
  <link name="act4Seg8">
    <visual>
      <origin xyz="0 0 0.075" rpy="0 0 0" />
      <geometry>
        <box size="0.4 0.4 0.15" />
      </geometry>
      <material name="blue">
        <color rgba="0.3 0.0 1 1.0" />
      </material>
    </visual>
    <collision>
      <origin xyz="0 0 0.075" rpy="0 0 0" />
      <geometry>
        <box size="0.4 0.4 0.15" />
      </geometry>
    </collision>
    <inertial>
      <mass value="0.15" />
      <inertia ixx="1" ixy="0" ixz="0" iyy="1" iyz="0" izz="1" />
    </inertial>
  </link>
  <joint name="act4Seg7_to_act4Seg8_ax1" type="revolute">
    <parent link="act4Seg7" />
    <child link="act4Seg8" />
    <origin xyz="0 0 0.15" rpy="0 0 0" />
    <axis xyz="0 1 0" />
    <limit lower="-3.141592" upper="3.141592" effort="100" velocity="3" />
  </joint>
  <link name="act4Seg8helper_shape">
    <visual>
      <origin xyz="0 0 0.0" rpy="-1.5707963267948966 0 0" />
      <geometry>
        <cylinder length="0.4" radius="0.2" />
      </geometry>
      <material name="blue">
        <color rgba="0.3 0.0 1 1.0" />
      </material>
    </visual>
    <collision>
      <origin xyz="0 0 0.0" rpy="-1.5707963267948966 0 0" />
      <geometry>
        <cylinder length="0.4" radius="0.2" />
      </geometry>
    </collision>
    <inertial>
      <mass value="0.00015" />
      <inertia ixx="0.001" ixy="0.0" ixz="0.0" iyy="0.001" iyz="0.0" izz="0.001" />
    </inertial>
  </link>
  <joint name="act4Seg7_to_act4Seg8_ax1helper_shape" type="fixed">
    <parent link="act4Seg7" />
    <child link="act4Seg8helper_shape" />
    <origin xyz="0 0 0.15" rpy="0 0 0" />
    <axis xyz="1 0 0" />
  </joint>
  <link name="act4Seg9">
    <visual>
      <origin xyz="0 0 0.075" rpy="0 0 0" />
      <geometry>
        <box size="0.4 0.4 0.15" />
      </geometry>
      <material name="blue">
        <color rgba="0.3 0.0 1 1.0" />
      </material>
    </visual>
    <collision>
      <origin xyz="0 0 0.075" rpy="0 0 0" />
      <geometry>
        <box size="0.4 0.4 0.15" />
      </geometry>
    </collision>
    <inertial>
      <mass value="0.15" />
      <inertia ixx="1" ixy="0" ixz="0" iyy="1" iyz="0" izz="1" />
    </inertial>
  </link>
  <joint name="act4Seg8_to_act4Seg9_ax0" type="revolute">
    <parent link="act4Seg8" />
    <child link="act4Seg9" />
    <origin xyz="0 0 0.15" rpy="0 0 0" />
    <axis xyz="1 0 0" />
    <limit lower="-3.141592" upper="3.141592" effort="100" velocity="3" />
  </joint>
  <link name="act4Seg9helper_shape">
    <visual>
      <origin xyz="0 0 0.0" rpy="0 -1.5707963267948966 0" />
      <geometry>
        <cylinder length="0.4" radius="0.2" />
      </geometry>
      <material name="blue">
        <color rgba="0.3 0.0 1 1.0" />
      </material>
    </visual>
    <collision>
      <origin xyz="0 0 0.0" rpy="0 -1.5707963267948966 0" />
      <geometry>
        <cylinder length="0.4" radius="0.2" />
      </geometry>
    </collision>
    <inertial>
      <mass value="0.00015" />
      <inertia ixx="0.001" ixy="0.0" ixz="0.0" iyy="0.001" iyz="0.0" izz="0.001" />
    </inertial>
  </link>
  <joint name="act4Seg8_to_act4Seg9_ax0helper_shape" type="fixed">
    <parent link="act4Seg8" />
    <child link="act4Seg9helper_shape" />
    <origin xyz="0 0 0.15" rpy="0 0 0" />
    <axis xyz="1 0 0" />
  </joint>
  <link name="act4Seg10">
    <visual>
      <origin xyz="0 0 0.0375" rpy="0 0 0" />
      <geometry>
        <box size="0.4 0.4 0.075" />
      </geometry>
      <material name="blue">
        <color rgba="0.3 0.0 1 1.0" />
      </material>
    </visual>
    <collision>
      <origin xyz="0 0 0.0375" rpy="0 0 0" />
      <geometry>
        <box size="0.4 0.4 0.075" />
      </geometry>
    </collision>
    <inertial>
      <mass value="0.15" />
      <inertia ixx="1" ixy="0" ixz="0" iyy="1" iyz="0" izz="1" />
    </inertial>
  </link>
  <joint name="act4Seg9_to_act4Seg10_ax1" type="revolute">
    <parent link="act4Seg9" />
    <child link="act4Seg10" />
    <origin xyz="0 0 0.15" rpy="0 0 0" />
    <axis xyz="0 1 0" />
    <limit lower="-3.141592" upper="3.141592" effort="100" velocity="3" />
  </joint>
  <link name="act4Seg10helper_shape">
    <visual>
      <origin xyz="0 0 0.0" rpy="-1.5707963267948966 0 0" />
      <geometry>
        <cylinder length="0.4" radius="0.2" />
      </geometry>
      <material name="blue">
        <color rgba="0.3 0.0 1 1.0" />
      </material>
    </visual>
    <collision>
      <origin xyz="0 0 0.0" rpy="-1.5707963267948966 0 0" />
      <geometry>
        <cylinder length="0.4" radius="0.2" />
      </geometry>
    </collision>
    <inertial>
      <mass value="0.00015" />
      <inertia ixx="0.001" ixy="0.0" ixz="0.0" iyy="0.001" iyz="0.0" izz="0.001" />
    </inertial>
  </link>
  <joint name="act4Seg9_to_act4Seg10_ax1helper_shape" type="fixed">
    <parent link="act4Seg9" />
    <child link="act4Seg10helper_shape" />
    <origin xyz="0 0 0.15" rpy="0 0 0" />
    <axis xyz="1 0 0" />
  </joint>
</robot>
